Workbook

Sheet Read Me
A1: Job responsibilities inventory - Specialty AR / denials
A2: What I handle: specialties, codes, providers, locations, payers, and the functions and tasks the role covers.
A4: Who this covers
A5: Linda Mora - specialty accounts receivable and denials. I work the specialty claim inventory from the first claim through to payment: research, correction, resubmission, appeal, and payment posting.
A7: Who I report to and who I work for
A8: Employer: 2Centric. Raquel is my manager at 2Centric and requested this inventory.
A9: Client: ASAP, a clinic. The claims in this inventory are ASAP's. Brianna is my direct lead at ASAP and the person I review most claims with. Deanne is the billing department manager at ASAP.
A11: How I prioritise the work
A12: 1. Claims still inside the payer's timely filing deadline come first, worked from the deadline that is closest to the one that is farthest out - the claim about to run out of window is the claim that gets worked.
A13: 2. Denials already past the filing deadline come second, reviewed for what can still be recovered through reconsideration, appeal, or a documented write-off.
A14: There is no target number of claims per day. The nature of the work does not support one - a claim may close in a single correction, or take several calls, a records submission and an appeal over weeks.
A16: What is in this workbook
... A27: Counts carried in from that file are shown in blue. Black figures are formulas calculated inside this workbook.

Sheet Specialties
A1: Specialties I handle
A2: Five specialties are mine day to day. Three more come to me on request. Code counts are live formulas over the 'Codes' tab.
A4: Code | B4: Specialty | C4: How I handle it | D4: Scope of work | E4: Total codes | F4: CPT | G4: HCPCS Level II | H4: Claim lines 2026 S1
A5: BH | B5: Behavioral Health | C5: Core - I own it | D5: Behavioral health integration and psychiatric collaborative care management delivered in the primary care setting. | E5: =COUNTIF(Codes!$A$5:$A$200,$A5) -> 4 | F5: =COUNTIFS(Codes!$A$5:$A$200,$A5,Codes!$C$5:$C$200,"CPT") -> 4 | G5: =COUNTIFS(Codes!$A$5:$A$200,$A5,Codes!$C$5:$C$200,"HCPCS Level II") -> 0 | H5: 323
A6: GAE | B6: Genicular Artery Embolization | C6: Core - I own it | D6: Image-guided embolization of the genicular arteries for knee osteoarthritis, including arterial access, selective catheterization and angiographic supervision and interpretation. | E6: =COUNTIF(Codes!$A$5:$A$200,$A6) -> 9 | F6: =COUNTIFS(Codes!$A$5:$A$200,$A6,Codes!$C$5:$C$200,"CPT") -> 9 | G6: =COUNTIFS(Codes!$A$5:$A$200,$A6,Codes!$C$5:$C$200,"HCPCS Level II") -> 0 | H6: 278
A7: US | B7: Ultrasound | C7: Core - I own it | D7: Non-invasive vascular ultrasound: extracranial, extremity arterial and venous duplex, physiologic arterial studies and visceral duplex. | E7: =COUNTIF(Codes!$A$5:$A$200,$A7) -> 5 | F7: =COUNTIFS(Codes!$A$5:$A$200,$A7,Codes!$C$5:$C$200,"CPT") -> 5 | G7: =COUNTIFS(Codes!$A$5:$A$200,$A7,Codes!$C$5:$C$200,"HCPCS Level II") -> 0 | H7: 157
A8: ORTHO | B8: Orthopedic | C8: Core - I own it | D8: Orthopedic and spine surgery: arthrodesis, instrumentation, disc arthroplasty, decompression, shoulder arthroscopy and neurostimulator implantation. | E8: =COUNTIF(Codes!$A$5:$A$200,$A8) -> 39 | F8: =COUNTIFS(Codes!$A$5:$A$200,$A8,Codes!$C$5:$C$200,"CPT") -> 39 | G8: =COUNTIFS(Codes!$A$5:$A$200,$A8,Codes!$C$5:$C$200,"HCPCS Level II") -> 0 | H8: 178
A9: DME | B9: Durable Medical Equipment | C9: Core - I own it | D9: Durable medical equipment and supplies, including collagen and other advanced wound dressings, spinal and lower/upper extremity orthoses, and TENS devices. | E9: =COUNTIF(Codes!$A$5:$A$200,$A9) -> 44 | F9: =COUNTIFS(Codes!$A$5:$A$200,$A9,Codes!$C$5:$C$200,"CPT") -> 1 | G9: =COUNTIFS(Codes!$A$5:$A$200,$A9,Codes!$C$5:$C$200,"HCPCS Level II") -> 43 | H9: 150
A10: POD | B10: Podiatry | C10: On request only | D10: Podiatry claims. Not one of my five core service lines - I do not carry the routine inventory for it. | E10: - | F10: - | G10: - | H10: -
A11: EMG | B11: Electromyography (EMG) | C11: On request only | D11: EMG and nerve conduction claims. Not one of my five core service lines - I do not carry the routine inventory for it. | E11: - | F11: - | G11: - | H11: -
A12: RTM | B12: Remote Therapeutic Monitoring (RTM) | C12: On request only | D12: Remote therapeutic monitoring claims. Not one of my five core service lines - I do not carry the routine inventory for it. | E12: - | F12: - | G12: - | H12: -
B14: Total - core specialties | E14: =SUM(E5:E9) -> 101 | F14: =SUM(F5:F9) -> 58 | G14: =SUM(G5:G9) -> 43 | H14: =SUM(H5:H9) -> 1086
A16: Brianna (my direct lead) and Deanne (billing department manager) sometimes ask me to review unsolved issues in podiatry, EMG and RTM. These are ad hoc reviews of unresolved claims, not a standing inventory - the codes, volumes and payers for them are not tracked in this workbook.

Sheet Codes
A1: CPT and HCPCS Level II codes I handle
A2: One row per code, with the official descriptor. Column A is colour-coded by specialty; the header row is filtered.
A4: Specialty | B4: Code | C4: Code Set | D4: Category | E4: Description | F4: Billing Notes | G4: On 2026 S1 claims
A5: BH | B5: 99484 | C5: CPT | D5: Behavioral Health Integration | E5: Care management services for behavioral health conditions, at least 20 minutes of clinical staff time, directed by a physician or other qualified health care professional, per calendar month | F5: General BHI. Time-based; report once per calendar month. | G5: Yes
A6: BH | B6: 99492 | C6: CPT | D6: Psychiatric Collaborative Care (CoCM) | E6: Initial psychiatric collaborative care management, first 70 minutes in the first calendar month of behavioral health care manager activities, in consultation with a psychiatric consultant, and directed by the treating physician or other qualified health care professional | F6: First calendar month of CoCM only. | G6: Yes
A7: BH | B7: 99493 | C7: CPT | D7: Psychiatric Collaborative Care (CoCM) | E7: Subsequent psychiatric collaborative care management, first 60 minutes in a subsequent month of behavioral health care manager activities, in consultation with a psychiatric consultant, and directed by the treating physician or other qualified health care professional | F7: Subsequent calendar months of CoCM. | G7: Yes
A8: BH | B8: 99494 | C8: CPT | D8: Psychiatric Collaborative Care (CoCM) | E8: Initial or subsequent psychiatric collaborative care management, each additional 30 minutes in a calendar month of behavioral health care manager activities, in consultation with a psychiatric consultant, and directed by the treating physician or other qualified health care professional | F8: Add-on code. Report with 99492 or 99493. | G8: Yes
A9: GAE | B9: 36140 | C9: CPT | D9: Arterial access | E9: Introduction of needle or intracatheter, upper or lower extremity artery | F9: NCCI bundles 36140 into 36245-36248; append modifier 59/XS only when a separate access site is documented. | G9: Yes
A10: GAE | B10: 36245 | C10: CPT | D10: Selective catheterization | E10: Selective catheter placement, arterial system; each first order abdominal, pelvic, or lower extremity artery branch, within a vascular family | F10: First order selective placement. | G10: Yes
A11: GAE | B11: 36246 | C11: CPT | D11: Selective catheterization | E11: Selective catheter placement, arterial system; initial second order abdominal, pelvic, or lower extremity artery branch, within a vascular family | F11: Second order selective placement. | G11: Yes
A12: GAE | B12: 36247 | C12: CPT | D12: Selective catheterization | E12: Selective catheter placement, arterial system; initial third order or more selective abdominal, pelvic, or lower extremity artery branch, within a vascular family | F12: Typical level of selectivity reached for genicular branches. | G12: Yes
A13: GAE | B13: 36248 | C13: CPT | D13: Selective catheterization | E13: Selective catheter placement, arterial system; additional second order, third order, and beyond, abdominal, pelvic, or lower extremity artery branch, within a vascular family | F13: Add-on code. Report with 36246 or 36247 for each additional branch in the same vascular family. | G13: Yes
A14: GAE | B14: 37242 | C14: CPT | D14: Embolization | E14: Vascular embolization or occlusion, inclusive of all radiological supervision and interpretation, intraprocedural roadmapping, and imaging guidance necessary to complete the intervention; non-central nervous system, non-head or neck (eg, congenital or acquired arterial malformations, arteriovenous malformations, arteriovenous fistulas, aneurysms, pseudoaneurysms) | F14: Primary embolization code for GAE. Includes all radiological S&I, roadmapping and imaging guidance. | G14: Yes
A15: GAE | B15: 75710 | C15: CPT | D15: Angiography S&I | E15: Angiography, extremity, unilateral, radiological supervision and interpretation | F15: Diagnostic extremity angiogram, one side. | G15: Yes
... A37: ORTHO | B37: 27279 | C37: CPT | D37: Sacroiliac arthrodesis | E37: Arthrodesis, sacroiliac joint, percutaneous or minimally invasive (indirect visualization), with image guidance, includes obtaining bone graft when performed, and placement of transfixing device | F37: Minimally invasive SI joint fusion. Image guidance and graft harvest are included. | G37: Yes
A38: ORTHO | B38: 29806 | C38: CPT | D38: Shoulder arthroscopy | E38: Arthroscopy, shoulder, surgical; capsulorrhaphy | G38: No
A39: ORTHO | B39: 29807 | C39: CPT | D39: Shoulder arthroscopy | E39: Arthroscopy, shoulder, surgical; repair of SLAP lesion | G39: No
A40: ORTHO | B40: 29819 | C40: CPT | D40: Shoulder arthroscopy | E40: Arthroscopy, shoulder, surgical; with removal of loose body or foreign body | G40: No
A41: ORTHO | B41: 29822 | C41: CPT | D41: Shoulder arthroscopy | E41: Arthroscopy, shoulder, surgical; debridement, limited, 1 or 2 discrete structures (eg, humeral bone, humeral articular cartilage, glenoid bone, glenoid articular cartilage, biceps tendon, biceps anchor complex, labrum, articular capsule, articular side of the rotator cuff, bursal side of the rotator cuff, subacromial bursa, foreign body[ies]) | F41: Limited debridement: 1 or 2 discrete structures. | G41: No
A42: ORTHO | B42: 29823 | C42: CPT | D42: Shoulder arthroscopy | E42: Arthroscopy, shoulder, surgical; debridement, extensive, 3 or more discrete structures (eg, humeral bone, humeral articular cartilage, glenoid bone, glenoid articular cartilage, biceps tendon, biceps anchor complex, labrum, articular capsule, articular side of the rotator cuff, bursal side of the rotator cuff, subacromial bursa, foreign body[ies]) | F42: Extensive debridement: 3 or more discrete structures. | G42: No
A43: ORTHO | B43: 29824 | C43: CPT | D43: Shoulder arthroscopy | E43: Arthroscopy, shoulder, surgical; distal claviculectomy including distal articular surface (Mumford procedure) | G43: No
A44: ORTHO | B44: 29827 | C44: CPT | D44: Shoulder arthroscopy | E44: Arthroscopy, shoulder, surgical; with rotator cuff repair | G44: No
A45: ORTHO | B45: 29828 | C45: CPT | D45: Shoulder arthroscopy | E45: Arthroscopy, shoulder, surgical; biceps tenodesis | G45: No
A46: ORTHO | B46: 63020 | C46: CPT | D46: Laminotomy / decompression | E46: Laminotomy (hemilaminectomy), with decompression of nerve root(s), including partial facetectomy, foraminotomy and/or excision of herniated intervertebral disc; 1 interspace, cervical | G46: No
A47: ORTHO | B47: 63030 | C47: CPT | D47: Laminotomy / decompression | E47: Laminotomy (hemilaminectomy), with decompression of nerve root(s), including partial facetectomy, foraminotomy and/or excision of herniated intervertebral disc; 1 interspace, lumbar | G47: Yes
A48: ORTHO | B48: 63035 | C48: CPT | D48: Laminotomy / decompression | E48: Laminotomy (hemilaminectomy), with decompression of nerve root(s), including partial facetectomy, foraminotomy and/or excision of herniated intervertebral disc; each additional interspace, cervical or lumbar | F48: Add-on code. Report with 63020-63030 or 63040-63042. | G48: Yes
A49: ORTHO | B49: 63040 | C49: CPT | D49: Laminotomy / re-exploration | E49: Laminotomy (hemilaminectomy), with decompression of nerve root(s), including partial facetectomy, foraminotomy and/or excision of herniated intervertebral disc, reexploration, single interspace; cervical | F49: Re-exploration at a previously operated interspace. | G49: No
A50: ORTHO | B50: 63042 | C50: CPT | D50: Laminotomy / re-exploration | E50: Laminotomy (hemilaminectomy), with decompression of nerve root(s), including partial facetectomy, foraminotomy and/or excision of herniated intervertebral disc, reexploration, single interspace; lumbar | F50: Re-exploration at a previously operated interspace. | G50: Yes
A51: ORTHO | B51: 63044 | C51: CPT | D51: Laminotomy / re-exploration | E51: Laminotomy (hemilaminectomy), with decompression of nerve root(s), including partial facetectomy, foraminotomy and/or excision of herniated intervertebral disc, reexploration, single interspace; each additional lumbar interspace | F51: Add-on code. Report with 63042. | G51: No
A52: ORTHO | B52: 63045 | C52: CPT | D52: Laminectomy / decompression | E52: Laminectomy, facetectomy and foraminotomy (unilateral or bilateral with decompression of spinal cord, cauda equina and/or nerve root[s], (eg, spinal or lateral recess stenosis)), single vertebral segment; cervical | G52: Yes
A53: ORTHO | B53: 63047 | C53: CPT | D53: Laminectomy / decompression | E53: Laminectomy, facetectomy and foraminotomy (unilateral or bilateral with decompression of spinal cord, cauda equina and/or nerve root[s], (eg, spinal or lateral recess stenosis)), single vertebral segment; lumbar | G53: Yes
A54: ORTHO | B54: 63048 | C54: CPT | D54: Laminectomy / decompression | E54: Laminectomy, facetectomy and foraminotomy (unilateral or bilateral with decompression of spinal cord, cauda equina and/or nerve root[s], (eg, spinal or lateral recess stenosis)), single vertebral segment; each additional segment, cervical, thoracic, or lumbar | F54: Add-on code. Report with 63045-63047. | G54: Yes
A55: ORTHO | B55: 63052 | C55: CPT | D55: Laminectomy with arthrodesis | E55: Laminectomy, facetectomy, or foraminotomy (unilateral or bilateral with decompression of spinal cord, cauda equina and/or nerve root[s], [eg, spinal or lateral recess stenosis]), during posterior interbody arthrodesis, lumbar; single vertebral segment | F55: Add-on code. Report with 22630, 22633, 22634. | G55: No
A56: ORTHO | B56: 63055 | C56: CPT | D56: Transpedicular decompression | E56: Transpedicular approach with decompression of spinal cord, equina and/or nerve root(s) (eg, herniated intervertebral disc), single segment; thoracic | G56: No
A57: ORTHO | B57: 63056 | C57: CPT | D57: Transpedicular decompression | E57: Transpedicular approach with decompression of spinal cord, equina and/or nerve root(s) (eg, herniated intervertebral disc), single segment; lumbar (including transfacet, or lateral extraforaminal approach) (eg, far lateral herniated intervertebral disc) | G57: No
A58: ORTHO | B58: 63057 | C58: CPT | D58: Transpedicular decompression | E58: Transpedicular approach with decompression of spinal cord, equina and/or nerve root(s) (eg, herniated intervertebral disc), single segment; each additional segment, thoracic or lumbar | F58: Add-on code. Report with 63055-63056. | G58: Yes
A59: ORTHO | B59: 63655 | C59: CPT | D59: Neurostimulator | E59: Laminectomy for implantation of neurostimulator electrodes, plate/paddle, epidural | F59: Paddle lead placement for spinal cord stimulation. | G59: Yes
A60: ORTHO | B60: 63685 | C60: CPT | D60: Neurostimulator | E60: Insertion or replacement of spinal neurostimulator pulse generator or receiver, requiring pocket creation and connection between electrode array and pulse generator or receiver | F60: IPG implant or replacement. | G60: Yes
A61: ORTHO | B61: 64708 | C61: CPT | D61: Peripheral nerve | E61: Neuroplasty, major peripheral nerve, arm or leg, open; other than specified | G61: Yes
A62: DME | B62: 97504 | C62: CPT | D62: Orthotic training (DELETED) | E62: Orthotic(s) fitting and training, upper extremity(s), lower extremity(s) and/or trunk, each 15 minutes -- CODE DELETED FROM CPT effective 01/01/2006 | F62: DELETED. Replaced by 97760 (orthotic management and training, initial encounter) and 97763 (subsequent encounter). Do not bill 97504 for current dates of service. | G62: No
...

Sheet Providers
A1: Providers I work with
A2: Rendering providers on the claims I work, as their names appear in the practice system.
A4: Rendering Provider | B4: Type | C4: Specialties | D4: Locations | E4: Claim lines 2026 S1
A5: HUNTER, DREW | B5: Individual provider | C5: GAE | D5: ASAP - DEER VALLEY; ASAP - Gilbert; ASAP Surgery Centers North Valley LLC; Premier Endoscopy Center, LLC | E5: 269
A6: LEATHEM, JARRETT | B6: Individual provider | C6: BH, US, ORTHO, DME | D6: ASAP - DEER VALLEY; ASAP - Gilbert; ASAP - Goodyear; ASAP Peoria; Premier Endoscopy Center, LLC | E6: 142
A7: TURLEY, TODD | B7: Individual provider | C7: BH, US, ORTHO, DME | D7: ASAP - Biltmore; ASAP - DEER VALLEY; ASAP - DEER VALLEY 240; ASAP - Gilbert; ASAP - Surprise - Reems; ASAP Peoria; ASAP Surgery Centers North Valley LLC | E7: 96
A8: BURGHER, ABRAM | B8: Individual provider | C8: BH, GAE, US, ORTHO | D8: ASAP - DEER VALLEY; ASAP - Gilbert; ASAP - Surprise - Reems; ASAP Peoria; ASAP Surgery Centers North Valley LLC | E8: 69
A9: LUKE, TIMOTHY | B9: Individual provider | C9: BH, ORTHO, DME | D9: ASAP - Avondale; ASAP - DEER VALLEY; ASAP - Gilbert; ASAP Prescott Valley; ASAP Surgery Centers North Valley LLC | E9: 62
A10: O'NEIL, ROY | B10: Individual provider | C10: BH, ORTHO, DME | D10: ASAP - Avondale; ASAP - DEER VALLEY; ASAP - Gilbert; ASAP - Goodyear; ASAP - Surprise - Reems; ASAP Peoria; ASAP Surgery Centers North Valley LLC | E10: 52
A11: MCCUNNIFF, PETER | B11: Individual provider | C11: ORTHO, DME | D11: ASAP Peoria; ASAP Surgery Centers North Valley LLC; Honor Health Deer Valley Medical Center | E11: 44
A12: SARKAR, AWNIK | B12: Individual provider | C12: BH, ORTHO, DME | D12: ASAP - DEER VALLEY; ASAP - Gilbert; ASAP - Surprise - Reems; ASAP Peoria; ASAP Surgery Centers North Valley LLC | E12: 44
A13: MEARS, CHAD | B13: Individual provider | C13: BH, ORTHO, DME | D13: ASAP - DEER VALLEY; ASAP - Gilbert; ASAP Peoria; ASAP Surgery Centers North Valley LLC | E13: 38
A14: MAYURAN, VIKRAM | B14: Individual provider | C14: ORTHO, DME | D14: ASAP - Mesa; ASAP Surgery Centers North Valley LLC; Banner Desert Medical Center | E14: 28
A15: MORALES, DAVID | B15: Individual provider | C15: BH, ORTHO, DME | D15: ASAP - DEER VALLEY; ASAP - Gilbert; ASAP Peoria; ASAP Sun City; ASAP Surgery Centers North Valley LLC | E15: 25
A16: KALLGREN, MARK | B16: Individual provider | C16: BH, ORTHO, DME | D16: ASAP - Gilbert; ASAP - Mesa; ASAP Peoria; Premier Endoscopy Center, LLC | E16: 24
... A40: WONG, KELLY | B40: Individual provider | C40: DME | D40: ASAP - Mesa | E40: 1
A42: Total | B42: =COUNTA(A5:A40)&" providers" -> 36 providers | E42: =SUM(E5:E40) -> 1086

Sheet Locations
A1: Locations I work with
A2: Service locations on the claims I work, as their names appear in the practice system.
A4: Location Name | B4: Type | C4: Specialties | D4: Providers | E4: Claim lines 2026 S1
A5: ASAP Surgery Centers North Valley LLC | B5: Surgery / procedure center | C5: GAE, ORTHO | D5: 12 | E5: 256
A6: ASAP - DEER VALLEY | B6: Clinic | C6: BH, GAE, US, ORTHO, DME | D6: 16 | E6: 193
A7: ASAP - Gilbert | B7: Clinic | C7: BH, GAE, US, DME | D7: 16 | E7: 189
A8: Premier Endoscopy Center, LLC | B8: Surgery / procedure center | C8: GAE, ORTHO | D8: 4 | E8: 123
A9: ASAP Peoria | B9: Clinic | C9: BH, DME | D9: 14 | E9: 85
A10: ASAP - Surprise - Reems | B10: Clinic | C10: BH, US, DME | D10: 7 | E10: 60
A11: ASAP - DEER VALLEY 240 | B11: Clinic | C11: US | D11: 1 | E11: 46
A12: Advanced Spine and Pain LLC DME - Surprise Reems | B12: DME location | C12: DME | D12: 2 | E12: 22
A13: Banner Desert Medical Center | B13: Hospital | C13: ORTHO | D13: 1 | E13: 18
A14: Advanced Spine and Pain LLC DME - Greenway | B14: DME location | C14: DME | D14: 1 | E14: 16
A15: ASAP - Avondale | B15: Clinic | C15: BH | D15: 3 | E15: 15
A16: ASAP - Goodyear | B16: Clinic | C16: BH, DME | D16: 3 | E16: 12
... A26: ASAP Sun City | B26: Clinic | C26: DME | D26: 1 | E26: 1
A28: Total | B28: =COUNTA(A5:A26)&" locations" -> 22 locations | E28: =SUM(E5:E26) -> 1086

Sheet Payers
A1: Payers I work with
A2: Every payer that appears on my claims as primary, secondary or responsible payer, with the timely filing carrier it maps to.
A4: Payer Name (as in the practice system) | B4: Appears as | C4: As primary | D4: As secondary | E4: As responsible payer | F4: Specialties | G4: Timely filing carrier | H4: Timely filing limit | I4: Days
A5: Medicare Part B Arizona * | B5: =SUBSTITUTE(TRIM(IF(C5>0,"Primary ","")&IF(D5>0,"Secondary ","")&IF(E5>0,"Responsible",""))," "," / ") -> Primary / Secondary / Responsible | C5: 246 | D5: 7 | E5: 137 | F5: BH, GAE, US, ORTHO | G5: MEDICARE | H5: 1 year | I5: 365
A6: UnitedHealthcare Community Plan / Arizona Long Term Care | B6: =SUBSTITUTE(TRIM(IF(C6>0,"Primary ","")&IF(D6>0,"Secondary ","")&IF(E6>0,"Responsible",""))," "," / ") -> Primary / Secondary / Responsible | C6: 104 | D6: 34 | E6: 107 | F6: BH, GAE, US, ORTHO, DME | G6: UHC COMMUNITY | H6: 90 days | I6: 90
A7: Blue Cross Blue Shield of Arizona (BCBS AZ) | B7: =SUBSTITUTE(TRIM(IF(C7>0,"Primary ","")&IF(D7>0,"Secondary ","")&IF(E7>0,"Responsible",""))," "," / ") -> Primary / Secondary / Responsible | C7: 95 | D7: 74 | E7: 120 | F7: BH, GAE, US, ORTHO, DME | G7: BCBS | H7: 365 days from DOS; 90 days as of 1/1/2026 | I7: 90
A8: Optum Care Medical Network of Arizona, Utah, & Washington (LifePrint) | B8: =SUBSTITUTE(TRIM(IF(C8>0,"Primary ","")&IF(D8>0,"Secondary ","")&IF(E8>0,"Responsible",""))," "," / ") -> Primary / Responsible | C8: 65 | D8: 0 | E8: 64 | F8: BH, GAE, US, ORTHO, DME | G8: OPTUM | H8: 90 days | I8: 90
A9: DME Region D | B9: =SUBSTITUTE(TRIM(IF(C9>0,"Primary ","")&IF(D9>0,"Secondary ","")&IF(E9>0,"Responsible",""))," "," / ") -> Primary / Secondary / Responsible | C9: 62 | D9: 1 | E9: 45 | F9: DME | G9: MEDICARE | H9: 1 year | I9: 365
A10: United Healthcare | B10: =SUBSTITUTE(TRIM(IF(C10>0,"Primary ","")&IF(D10>0,"Secondary ","")&IF(E10>0,"Responsible",""))," "," / ") -> Primary / Secondary / Responsible | C10: 60 | D10: 10 | E10: 62 | F10: BH, US, ORTHO, DME | G10: UHC COMMERCIAL | H10: 90 days | I10: 90
A11: AARP United Healthcare | B11: =SUBSTITUTE(TRIM(IF(C11>0,"Primary ","")&IF(D11>0,"Secondary ","")&IF(E11>0,"Responsible",""))," "," / ") -> Secondary / Responsible | C11: 0 | D11: 56 | E11: 18 | F11: BH, GAE, US, ORTHO, DME | G11: AARP MA CHOICE / MEDICARE COMPLETE | H11: Not documented | I11: -
A12: Humana Gold Plus HMO | B12: =SUBSTITUTE(TRIM(IF(C12>0,"Primary ","")&IF(D12>0,"Secondary ","")&IF(E12>0,"Responsible",""))," "," / ") -> Primary / Responsible | C12: 49 | D12: 0 | E12: 47 | F12: BH, GAE, US, ORTHO, DME | G12: HUMANA MA | H12: 180 days from DOS (physicians); 90 days from DOS (ancillary providers) | I12: 90
A13: UHC Group Medicare Advantage | B13: =SUBSTITUTE(TRIM(IF(C13>0,"Primary ","")&IF(D13>0,"Secondary ","")&IF(E13>0,"Responsible",""))," "," / ") -> Primary / Responsible | C13: 36 | D13: 0 | E13: 36 | F13: BH, GAE, US, ORTHO, DME | G13: UHC MA | H13: 90 days | I13: 90
A14: Aetna Legacy | B14: =SUBSTITUTE(TRIM(IF(C14>0,"Primary ","")&IF(D14>0,"Secondary ","")&IF(E14>0,"Responsible",""))," "," / ") -> Primary / Secondary / Responsible | C14: 31 | D14: 13 | E14: 40 | F14: BH, GAE, US, ORTHO | G14: AETNA | H14: 120 days per contract | I14: 120
A15: United HealthCare Dual Complete | B15: =SUBSTITUTE(TRIM(IF(C15>0,"Primary ","")&IF(D15>0,"Secondary ","")&IF(E15>0,"Responsible",""))," "," / ") -> Primary / Secondary / Responsible | C15: 30 | D15: 3 | E15: 30 | F15: BH, GAE, US | G15: UHC DUAL COMPLETE | H15: 365 days | I15: 365
A16: HealthSpring Medicare Advantage | B16: =SUBSTITUTE(TRIM(IF(C16>0,"Primary ","")&IF(D16>0,"Secondary ","")&IF(E16>0,"Responsible",""))," "," / ") -> Primary / Responsible | C16: 28 | D16: 0 | E16: 28 | F16: GAE, US, ORTHO, DME | G16: CIGNA / CIGNA MEDICARE | H16: 90 days from DOS | I16: 90
A17: Alignment Health Care | B17: =SUBSTITUTE(TRIM(IF(C17>0,"Primary ","")&IF(D17>0,"Secondary ","")&IF(E17>0,"Responsible",""))," "," / ") -> Primary / Responsible | C17: 26 | D17: 0 | E17: 26 | F17: BH, GAE, ORTHO, DME | G17: Not mapped | H17: No limit on file - needs research | I17: -
A18: Mercy Care Plan (AHCCCS) - Complete Care & Long Term Care (LTC) | B18: =SUBSTITUTE(TRIM(IF(C18>0,"Primary ","")&IF(D18>0,"Secondary ","")&IF(E18>0,"Responsible",""))," "," / ") -> Primary / Secondary / Responsible | C18: 17 | D18: 25 | E18: 21 | F18: BH, GAE, US, ORTHO, DME | G18: MERCY CARE MEDICAID | H18: 180 days | I18: 180
A19: UMR Wausau / UHIS | B19: =SUBSTITUTE(TRIM(IF(C19>0,"Primary ","")&IF(D19>0,"Secondary ","")&IF(E19>0,"Responsible",""))," "," / ") -> Primary / Responsible | C19: 23 | D19: 0 | E19: 23 | F19: BH, GAE, US, ORTHO | G19: UMR / WAUSAU | H19: Not documented - third party administrator, the plan document sets the limit | I19: -
A20: Gold Kidney Health Plan | B20: =SUBSTITUTE(TRIM(IF(C20>0,"Primary ","")&IF(D20>0,"Secondary ","")&IF(E20>0,"Responsible",""))," "," / ") -> Primary / Responsible | C20: 22 | D20: 0 | E20: 22 | F20: BH, GAE, ORTHO, DME | G20: Not mapped | H20: No limit on file - needs research | I20: -
A21: Tricare for Life (All Regions) | B21: =SUBSTITUTE(TRIM(IF(C21>0,"Primary ","")&IF(D21>0,"Secondary ","")&IF(E21>0,"Responsible",""))," "," / ") -> Primary / Secondary / Responsible | C21: 2 | D21: 20 | E21: 9 | F21: BH, US, ORTHO, DME | G21: Not mapped | H21: No limit on file - needs research | I21: -
A22: Banner Health & Aetna Health Insurance Company | B22: =SUBSTITUTE(TRIM(IF(C22>0,"Primary ","")&IF(D22>0,"Secondary ","")&IF(E22>0,"Responsible",""))," "," / ") -> Primary / Responsible | C22: 19 | D22: 0 | E22: 19 | F22: BH, GAE, US, ORTHO | G22: BANNER HEALTH & AETNA | H22: 120 days | I22: 120
A23: Arizona Complete Health (Centene) | B23: =SUBSTITUTE(TRIM(IF(C23>0,"Primary ","")&IF(D23>0,"Secondary ","")&IF(E23>0,"Responsible",""))," "," / ") -> Primary / Secondary / Responsible | C23: 3 | D23: 17 | E23: 4 | F23: BH, GAE, US, ORTHO, DME | G23: AZ COMPLETE | H23: 120 days | I23: 120
A24: Bankers Life Colonial Penn Life | B24: =SUBSTITUTE(TRIM(IF(C24>0,"Primary ","")&IF(D24>0,"Secondary ","")&IF(E24>0,"Responsible",""))," "," / ") -> Secondary / Responsible | C24: 0 | D24: 17 | E24: 11 | F24: BH, GAE, US, DME | G24: Not mapped | H24: No limit on file - needs research | I24: -
A25: AARP MedicareComplete (SecureHorizons & Oxford Network) | B25: =SUBSTITUTE(TRIM(IF(C25>0,"Primary ","")&IF(D25>0,"Secondary ","")&IF(E25>0,"Responsible",""))," "," / ") -> Primary / Responsible | C25: 15 | D25: 0 | E25: 15 | F25: BH, US, ORTHO, DME | G25: AARP MA CHOICE / MEDICARE COMPLETE | H25: Not documented | I25: -
A26: Devoted Health Plan | B26: =SUBSTITUTE(TRIM(IF(C26>0,"Primary ","")&IF(D26>0,"Secondary ","")&IF(E26>0,"Responsible",""))," "," / ") -> Primary / Responsible | C26: 15 | D26: 0 | E26: 15 | F26: GAE, US, ORTHO, DME | G26: DEVOTED | H26: 60 days | I26: 60
A27: COMBINED INSURANCE CO OF AMERICA | B27: =SUBSTITUTE(TRIM(IF(C27>0,"Primary ","")&IF(D27>0,"Secondary ","")&IF(E27>0,"Responsible",""))," "," / ") -> Secondary / Responsible | C27: 0 | D27: 14 | E27: 14 | F27: GAE | G27: Not mapped | H27: No limit on file - needs research | I27: -
A28: TRIWEST VA CCN CLAIMS | B28: =SUBSTITUTE(TRIM(IF(C28>0,"Primary ","")&IF(D28>0,"Secondary ","")&IF(E28>0,"Responsible",""))," "," / ") -> Primary / Responsible | C28: 14 | D28: 0 | E28: 14 | F28: BH, US, ORTHO, DME | G28: VETERANS ADMIN (VA CCN) | H28: 180 days | I28: 180
A29: Humana | B29: =SUBSTITUTE(TRIM(IF(C29>0,"Primary ","")&IF(D29>0,"Secondary ","")&IF(E29>0,"Responsible",""))," "," / ") -> Primary / Secondary / Responsible | C29: 12 | D29: 3 | E29: 11 | F29: GAE, US, ORTHO, DME | G29: HUMANA COMMERCIAL | H29: 180 days from DOS (physicians); 90 days from DOS (ancillary providers) | I29: 90
A30: Aetna Senior Supplemental (AESSI) - Secondary Only 62118 | B30: =SUBSTITUTE(TRIM(IF(C30>0,"Primary ","")&IF(D30>0,"Secondary ","")&IF(E30>0,"Responsible",""))," "," / ") -> Secondary / Responsible | C30: 0 | D30: 11 | E30: 2 | F30: BH, GAE, US, DME | G30: Not mapped | H30: No limit on file - needs research | I30: -
A31: Mercy Care Health Plan Advantage (AHCCCS) | B31: =SUBSTITUTE(TRIM(IF(C31>0,"Primary ","")&IF(D31>0,"Secondary ","")&IF(E31>0,"Responsible",""))," "," / ") -> Primary / Secondary / Responsible | C31: 3 | D31: 10 | E31: 5 | F31: BH, GAE, US | G31: MERCY CARE ADVANTAGE | H31: 150 days from DOS or eligibility posting, whichever is later | I31: 150
A32: Aetna Medicare PPO | B32: =SUBSTITUTE(TRIM(IF(C32>0,"Primary ","")&IF(D32>0,"Secondary ","")&IF(E32>0,"Responsible",""))," "," / ") -> Primary / Responsible | C32: 9 | D32: 0 | E32: 8 | F32: BH, GAE, US, DME | G32: AETNA | H32: 120 days per contract | I32: 120
A33: Aetna | B33: =SUBSTITUTE(TRIM(IF(C33>0,"Primary ","")&IF(D33>0,"Secondary ","")&IF(E33>0,"Responsible",""))," "," / ") -> Primary / Responsible | C33: 8 | D33: 0 | E33: 8 | F33: US, ORTHO | G33: AETNA | H33: 120 days per contract | I33: 120
A34: Banner University Family Care / ACC (AHCCS Complete Care) | B34: =SUBSTITUTE(TRIM(IF(C34>0,"Primary ","")&IF(D34>0,"Secondary ","")&IF(E34>0,"Responsible",""))," "," / ") -> Secondary / Responsible | C34: 0 | D34: 8 | E34: 1 | F34: BH, US | G34: Not mapped | H34: No limit on file - needs research | I34: -
A35: ChampVA - HAC | B35: =SUBSTITUTE(TRIM(IF(C35>0,"Primary ","")&IF(D35>0,"Secondary ","")&IF(E35>0,"Responsible",""))," "," / ") -> Secondary / Responsible | C35: 0 | D35: 8 | E35: 5 | F35: BH, ORTHO | G35: Not mapped | H35: No limit on file - needs research | I35: -
A36: Health Choice Arizona | B36: =SUBSTITUTE(TRIM(IF(C36>0,"Primary ","")&IF(D36>0,"Secondary ","")&IF(E36>0,"Responsible",""))," "," / ") -> Primary / Secondary / Responsible | C36: 8 | D36: 2 | E36: 8 | F36: BH, GAE, DME | G36: HEALTH CHOICE MEDICAID | H36: 6 months (not primary) or 7 months (primary) | I36: 180
A37: Mercy Care RBHA | B37: =SUBSTITUTE(TRIM(IF(C37>0,"Primary ","")&IF(D37>0,"Secondary ","")&IF(E37>0,"Responsible",""))," "," / ") -> Primary / Secondary / Responsible | C37: 2 | D37: 8 | E37: 2 | F37: BH, US, DME | G37: MERCY CARE MEDICAID | H37: 180 days | I37: 180
A38: Mutual of Omaha Insurance Company | B38: =SUBSTITUTE(TRIM(IF(C38>0,"Primary ","")&IF(D38>0,"Secondary ","")&IF(E38>0,"Responsible",""))," "," / ") -> Secondary / Responsible | C38: 0 | D38: 8 | E38: 5 | F38: BH, US, DME | G38: Not mapped | H38: No limit on file - needs research | I38: -
A39: Physicians Mutual Insurance Company - ENS | B39: =SUBSTITUTE(TRIM(IF(C39>0,"Primary ","")&IF(D39>0,"Secondary ","")&IF(E39>0,"Responsible",""))," "," / ") -> Secondary / Responsible | C39: 0 | D39: 8 | E39: 1 | F39: BH, US, ORTHO, DME | G39: Not mapped | H39: No limit on file - needs research | I39: -
A40: USAA Life Insurance Company | B40: =SUBSTITUTE(TRIM(IF(C40>0,"Primary ","")&IF(D40>0,"Secondary ","")&IF(E40>0,"Responsible",""))," "," / ") -> Secondary / Responsible | C40: 0 | D40: 8 | E40: 1 | F40: GAE, US, ORTHO | G40: Not mapped | H40: No limit on file - needs research | I40: -
A41: Unicare Life and Health Insurance (Anthem) | B41: =SUBSTITUTE(TRIM(IF(C41>0,"Primary ","")&IF(D41>0,"Secondary ","")&IF(E41>0,"Responsible",""))," "," / ") -> Secondary / Responsible | C41: 0 | D41: 8 | E41: 7 | F41: GAE, DME | G41: Not mapped | H41: No limit on file - needs research | I41: -
...

Sheet Functions & Tasks
A1: My functions and tasks
A2: What the role consists of. Rows 1-3 set the order the work is taken in; the rest are the actions a claim can need.
A4: # | B4: Area | C4: Function / task | D4: What it involves | E4: Who I work with on it | F4: When it comes up
A5: 1 | B5: Work queue and order | C5: Work claims inside the timely filing window first | D5: The queue is ordered by how much time is left to file. I take the claim whose timely filing deadline is closest first and work outward from there, to the ones with the most time left. A claim that runs out of window is money that cannot be recovered, so the window drives the order, not the balance. | E5: Self; deadlines from the carrier timely filing reference | F5: Every day - this is the top of the queue
A6: 2 | B6: Work queue and order | C6: Then work denials that are already past due | D6: Once the claims still inside the filing window are handled, I go back through denials whose deadline has already passed to see what is still recoverable - a late-filing appeal with proof of timely submission, a reconsideration the payer still accepts, or a documented write-off. | E6: Brianna (lead) | F6: After the in-window claims are cleared
A7: 3 | B7: Work queue and order | C7: No fixed daily claim target | D7: There is no set number of claims to close per day, and the work does not support one. One claim can close with a single corrected submission; the next needs a payer call, a records submission, an appeal, and weeks of follow-up. Throughput varies with what the claims need, not with effort. | E7: Raquel (2Centric manager) - noted for expectation setting | F7: Standing - describes the role
A8: 4 | B8: Research | C8: Research why payment for a procedure was denied | D8: This is the main body of the work. I read the denial on the EOB or ERA and work back through the claim - procedure code, modifiers, units, diagnosis linkage, place of service, provider, authorization, eligibility, coordination of benefits, network status - until I find the actual reason the payer did not pay, rather than the reason printed on the remittance. | E8: Self | F8: Every denied or underpaid claim
A9: 5 | B9: Research | C9: Call the insurance for denial detail | D9: When the remittance is not specific enough to act on, I call the payer to get the real denial reason, what they need to reprocess, whether it goes back as a correction or an appeal, and the reference number for the call. | E9: Payer representatives | F9: When the remittance is not actionable on its own
A10: 6 | B10: Coordination | C10: Work coding issues with the billers | D10: When the denial points at how the claim was coded - the procedure code, a modifier, units, or how the diagnosis was linked - I take it back to the biller who coded it so the correction is right before it goes back out. | E10: Billing / coding team | F10: Coding, modifier, unit and diagnosis denials
A11: 7 | B11: Coordination | C11: Review claims with the provider | D11: Some questions are clinical, not administrative - what was actually performed, what the documentation supports, whether the service was medically necessary as billed. Those I take to the rendering provider directly. | E11: Rendering providers | F11: Medical necessity and documentation questions
A12: 8 | B12: Coordination | C12: Escalate to the authorizations team | D12: When the denial is for a missing, expired, or mismatched prior authorization, I hand it to the authorizations team to locate or obtain the auth, then rework the claim once they come back. | E12: Authorizations team | F12: Auth-related denials
A13: 9 | B13: Coordination | C13: Escalate to the credentialing team | D13: When the problem is whether the provider is in network with that payer, or whether their effective date covers the date of service, it goes to credentialing. | E13: Credentialing team | F13: Network status and provider enrollment denials
A14: 10 | B14: Coordination | C14: Review claims with Brianna | D14: Brianna is my main review path. Most claims I work get reviewed with her - the approach before I take it, or the outcome after - and she is who I go to when a claim does not fit a standard route. | E14: Brianna (direct lead, ASAP) | F14: Ongoing - the primary review channel
A15: 11 | B15: Claim action | C15: Resubmit claims that need correction | D15: Rebill the claim with the correction applied - code, modifier, units, place of service, payer, or patient and insurance details - inside the payer's corrected claim window, carrying the original claim reference number so it is treated as a correction and not a duplicate. | E15: Billers where the correction is a coding change | F15: Once the cause is identified and the fix is a correction
A16: 12 | B16: Claim action | C16: Submit medical records | D16: Send the payer what they have asked for to support the claim - office notes, operative reports, orders, proof of delivery on DME - through the route that payer accepts. | E16: Providers and clinic staff for the documentation | F16: Records requests and documentation denials
... A24: 20 | B24: Ad hoc | C24: Review unsolved issues in podiatry, EMG and RTM | D24: Brianna and Deanne sometimes ask me to review unresolved claims in podiatry, EMG and remote therapeutic monitoring. These sit outside my five core specialties - I pick them up as one-off reviews rather than carrying a standing inventory for them. | E24: Brianna (lead); Deanne (billing department manager) | F24: On request

Sheet Notes & Sources
A1: Notes, assumptions and sources
A4: Where each part of this workbook comes from
A5: 'Specialties' - the five core specialties, their codes and their scope descriptions come from 'Specialty_CPT_HCPCS_Code_Reference.xlsx' in this repository. Podiatry, EMG and RTM were supplied by me and are not in that file; they have no code list, volume or payer set here because I do not carry a standing inventory for them.
A6: 'Codes' - copied from the 'Code Master' tab of 'Specialty_CPT_HCPCS_Code_Reference.xlsx', 101 codes across the five specialties. The 'On 2026 S1 claims' column was calculated by matching each code against the procedure codes on the 1,086 pending claim lines - 46 of the codes appear there. A 'No' does not mean the code is not mine; it means no pending claim in that snapshot carries it.
A7: 'Providers', 'Locations', 'Payers' - taken from the 'Merged' sheet of 'Specialty Claims Pending 2026-S1.xlsx' (1,086 claim lines, dates of service 01/05/2026 to 06/30/2026). Names are reproduced exactly as they appear in the practice system, including inconsistent capitalisation, so they match when searched.
A8: 'Payers' timely filing columns - matched through column O ('Likely Payer Name(s) in AR Data') of 'Carrier_Timely_Filing_Reference.xlsx'. 40 of the 85 payer names map to a carrier row; the remaining 45 are marked 'Not mapped'.
A9: 'Functions & Tasks' - supplied by me, describing the role as it is actually worked. Not taken from a written job description.
A11: Assumptions and caveats
A12: Claim-line counts are a snapshot of pending AR at the time that file was pulled. They show where the volume sits across specialties, providers, locations and payers - they are not a record of everything worked, and not a productivity figure.
A13: A claim line is one procedure line, not one claim. A claim with three procedure codes contributes three lines, so provider and location counts reflect billed lines rather than patient encounters.
A14: The three payer counts overlap. Every claim has a primary payer and one responsible payer, and may have a secondary payer; the responsible payer is whichever one currently holds the balance. Do not add the three columns together.
A15: 'LIEN 03' and 'LIEN 05' appear in the payer field but are lien accounts, not insurance carriers. They are kept in the list because claims sit under them.
... A24: Prepared August 2026 by Linda Mora, at the request of Raquel (2Centric). The claims described are worked for ASAP, where Brianna is the direct lead and Deanne is the billing department manager.
