Workbook

Sheet Read Me
A1: Timely filing 10 day watchlist - Specialty Claims Pending 2026-S1
A2: Pending claims whose timely filing deadline, based on the primary payer, falls within the next 10 days.
A4: Snapshot date (filter applied) | B4: 46244
A5: Window (days to deadline) | B5: 0 to 10
A6: Claims on the watchlist | B6: 47
A8: How the watchlist was built
A9: 1. Source: the 'Merged' sheet of 'Specialty Claims Pending 2026-S1.xlsx' (1086 claim lines).
A10: 2. Each claim's Primary Payer Name was matched to a carrier in 'Carrier_Timely_Filing_Reference.xlsx' using column F of its 'Timely Filing' tab (Likely Payer Name(s) in AR Data). Responsible Payer was not used - the filter is driven by the primary payer, as requested.
A11: 3. Filing Deadline = Date of Service + the carrier's timely filing limit. The deadline is a live formula (Date of Service + Timely Filing Limit), and Days Until Deadline recalculates against TODAY() every time the file is opened.
A12: 4. A claim is on the watchlist when its deadline is between 0 and 10 days away as of the snapshot date above.
A14: What happened to the other claims
A15: Bucket | B15: Claim lines | F15: Note
A16: On this watchlist (0-10 days) | B16: 47 | F16: Included in this workbook.
A17: Deadline more than 10 days away | B17: 634 | F17: Not urgent yet - not included.
A18: Deadline already passed | B18: 281 | F18: Past the filing limit as of the snapshot date. Outside what was asked for, but worth a separate appeal / write-off review.
A19: No timely filing limit on file | B19: 124 | F19: Primary payer has no limit in the reference file, or no matching payer name. Listed on the 'Payers Needing Limits' tab - a deadline cannot be calculated for these.
A20: Total claim lines in source file | B20: 1086
A22: Watchlist by specialty (live counts)
A23: Tab | B23: Specialty | C23: Claim lines | D23: Balance at risk
A24: BH | B24: Behavioral Health | C24: =COUNTA('BH'!C5:C69) | D24: =SUM('BH'!W5:W69)
A25: DME | B25: Durable Medical Equipment | C25: =COUNTA('DME'!C5:C60) | D25: =SUM('DME'!W5:W60)
A26: GAE | B26: Genicular Artery Embolization | C26: =COUNTA('GAE'!C5:C56) | D26: =SUM('GAE'!W5:W56)
A27: ORTHO | B27: Orthopedic | C27: =COUNTA('ORTHO'!C5:C66) | D27: =SUM('ORTHO'!W5:W66)
A28: US | B28: Ultrasound | C28: =COUNTA('US'!C5:C72) | D28: =SUM('US'!W5:W72)
A29: TOTAL | C29: =SUM(C24:C28) | D29: =SUM(D24:D28)
A31: How to use the workbook
A32: Amber cells are yours to fill in. On each specialty tab, Claim Status (column A) and Notes (column B) are the only editable columns - Claim Status has a drop-down of the values already used in the source file, but you can type anything.
A33: The 'All Claims' tab repeats every watchlist claim with no specialty split. Its Claim Status and Notes cells are formulas pointing at the matching row on the specialty tab, so anything you type on a specialty tab appears there as soon as the sheet recalculates. Do not type over columns A and B of 'All Claims' - that would break the link. The last column on that tab names the exact cell each row is linked to.
A34: Every tab has a filter on the header row and a frozen header. Days Until Deadline is shaded red at 3 days or less, amber at 4-7 days and green above 7.
A35: The claims are unchanged copies of the source rows; nothing has been re-keyed. One row is one claim line (procedure code), so a claim with several procedure codes appears on several rows.
A37: Assumptions and caveats
A38: - Humana and Humana Gold Plus HMO carry two limits - 180 days for physicians and 90 for ancillary providers. The shorter 90 days is applied so nothing is missed; confirm the provider category before relying on it. Flagged in the Limit Basis / Caveat column. (Using 180 days instead would change one claim on this watchlist.)
A39: - TRIWEST VA CCN CLAIMS covers two programmes with different limits - TriWest at 120 days and VA CCN at 180. The shorter 120 days is applied. No claim under this payer reaches the 10 day window either way.
A40: - Blue Cross Blue Shield of Arizona moved from 365 to 90 days effective 01/01/2026. Every date of service in the source file is in 2026, so 90 days applies throughout.
A41: - Health Choice Arizona (7 calendar months) and Health Choice Pathway (6 calendar months) are stated in months, so their deadlines are counted in calendar months rather than a fixed day count. No Health Choice claim reaches the 10 day window, so every deadline formula in this workbook is a simple day count.
A42: - Banner University MA and Banner University Medicaid are recorded at 120 days but flagged by the practice as needing verification against the contract. Aetna's 120 days comes from our contract rather than a published policy.
A43: - Limits are counted from the date of service. Secondary claims are commonly counted from the primary carrier's remittance date instead - that is not captured in the reference file and should be checked per carrier for any row with a Secondary Payer Name.
... A47: Sources: Specialty Claims Pending 2026-S1.xlsx (Merged tab) and Carrier_Timely_Filing_Reference.xlsx (Timely Filing tab), both in the repository root. Generated 10 August 2026.

Sheet Payers Needing Limits
A1: Primary payers with no timely filing limit on file
A2: These claim lines could not be given a deadline, so they are not on the watchlist. Either the carrier has no limit in Carrier_Timely_Filing_Reference.xlsx, or the payer name in the AR data has no match in column F of its Timely Filing tab. Get the limit from the contract or the current provider manual, then re-run the watchlist.
A4: Primary Payer Name | B4: Claim lines | C4: Insurance balance | D4: Earliest date of service | E4: Latest date of service
A5: Alignment Health Care | B5: 26 | C5: 52359.41 | D5: 46062 | E5: 46198
A6: UMR Wausau / UHIS | B6: 23 | C6: 159298.16 | D6: 46034 | E6: 46195
A7: Gold Kidney Health Plan | B7: 22 | C7: 113729.42 | D7: 46045 | E7: 46197
A8: AARP MedicareComplete (SecureHorizons & Oxford Network) | B8: 15 | C8: 36511.16 | D8: 46058 | E8: 46198
A9: Imperial Insurance Companies Inc Exchange AZ (IEXAZ) (WAYSTAR ONLY) | B9: 6 | C9: 12620.93 | D9: 46108 | E9: 46190
A10: SCAN Health Plan (Village Health Plan) | B10: 4 | C10: 3546.2 | D10: 46182 | E10: 46190
A11: Meritain Health | B11: 4 | C11: 17028.69 | D11: 46178 | E11: 46202
A12: Medica Health Plan Solutions (Mayo Plan - CHI Health) | B12: 4 | C12: 2799.16 | D12: 46045 | E12: 46101
A13: Banner University Care Dual Advantage Plan | B13: 3 | C13: 349.84 | D13: 46104 | E13: 46198
A14: Medicare Railroad (RR Medicare MetraHealth) 00882 | B14: 3 | C14: 36397.19 | D14: 46104 | E14: 46133
A15: Mercy Care Health Plan Advantage (AHCCCS) | B15: 3 | C15: 3822.49 | D15: 46177 | E15: 46177
A16: AFSAT MEDICAL PLAN | B16: 2 | C16: 9056.39 | D16: 46127 | E16: 46127
... A21: DME Region C | B21: 1 | C21: 72707.6 | D21: 46076 | E21: 46076
A22: TOTAL | B22: =SUM(B5:B21) | C22: =SUM(C5:C21)

Sheet BH
A1: Behavioral Health (BH) - timely filing 10 day watchlist
A2: Claims whose primary payer timely filing deadline falls within 10 days of 10 August 2026. Fill in the amber Claim Status and Notes columns - they feed the All Claims tab automatically. Every other column is copied from the source file or calculated.
A4: Claim Status | B4: Notes | C4: Primary Claim ID | D4: Chart Number | E4: Responsible Payer | F4: Primary Payer Name | G4: Secondary Payer Name | H4: Date of Service | I4: Procedure Code | J4: Specialty | K4: Filing Deadline | L4: Days Until Deadline | M4: Timely Filing Limit (Days) | N4: Reference Carrier | O4: Limit Basis / Caveat | P4: Modifier 1 | Q4: Modifier 2 | R4: Modifier 3 | S4: Units | T4: Charge Amount | U4: Insurance Payment | V4: Adjustment | W4: Insurance Balance | X4: AR Age by Service Date | Y4: Rendering Provider | Z4: Location Name | AA4: Secondary Claim ID | AB4: Created Date | AC4: Insurance Check Date | AD4: Diagnosis Code 1 | AE4: Diagnosis Code 2 | AF4: Diagnosis Code 3 | AG4: Diagnosis Code 4
A5: Received | C5: 559340053 | D5: HF458717535 | E5: Blue Cross Blue Shield of Arizona (BCBS AZ) | F5: Blue Cross Blue Shield of Arizona (BCBS AZ) | G5: No Payer | H5: 46154 | I5: 99492 | J5: BH | K5: =H5+M5 | L5: =K5-TODAY() | M5: 90 | N5: BCBS | O5: Limit cut from 365 to 90 days effective 01/01/2026; 90 applies because the date of service is in 2026. | S5: 1 | T5: 1029.98 | U5: 0 | V5: 0 | W5: 826.36 | X5: 88 | Y5: SARKAR, AWNIK | Z5: ASAP Peoria | AB5: 46180 | AC5: 46216 | AD5: F4320
A6: Received | C6: 559340053 | D6: HF458717535 | E6: Blue Cross Blue Shield of Arizona (BCBS AZ) | F6: Blue Cross Blue Shield of Arizona (BCBS AZ) | G6: No Payer | H6: 46154 | I6: 99494 | J6: BH | K6: =H6+M6 | L6: =K6-TODAY() | M6: 90 | N6: BCBS | O6: Limit cut from 365 to 90 days effective 01/01/2026; 90 applies because the date of service is in 2026. | S6: 1 | T6: 396.27 | U6: 0 | V6: 0 | W6: 317.94 | X6: 88 | Y6: SARKAR, AWNIK | Z6: ASAP Peoria | AB6: 46180 | AC6: 46216 | AD6: F4320
C7: 559331282 | D7: HF479934906 | E7: United Healthcare | F7: United Healthcare | G7: No Payer | H7: 46156 | I7: 99493 | J7: BH | K7: =H7+M7 | L7: =K7-TODAY() | M7: 90 | N7: UHC COMMERCIAL | S7: 1 | T7: 976.64 | U7: 0 | V7: 0 | W7: 976.64 | X7: 86 | Y7: MEARS, CHAD | Z7: ASAP - DEER VALLEY | AB7: 46180 | AD7: F4312
C8: 559331282 | D8: HF479934906 | E8: United Healthcare | F8: United Healthcare | G8: No Payer | H8: 46156 | I8: 99494 | J8: BH | K8: =H8+M8 | L8: =K8-TODAY() | M8: 90 | N8: UHC COMMERCIAL | S8: 1 | T8: 396.27 | U8: 0 | V8: 0 | W8: 396.27 | X8: 86 | Y8: MEARS, CHAD | Z8: ASAP - DEER VALLEY | AB8: 46180 | AD8: F4312
C9: 559334288 | D9: HF555357253 | E9: United Healthcare | F9: United Healthcare | G9: No Payer | H9: 46156 | I9: 99492 | J9: BH | K9: =H9+M9 | L9: =K9-TODAY() | M9: 90 | N9: UHC COMMERCIAL | S9: 1 | T9: 1029.98 | U9: 0 | V9: 0 | W9: 1029.98 | X9: 86 | Y9: MEARS, CHAD | Z9: ASAP - DEER VALLEY | AB9: 46180 | AD9: F4320
C10: 559334288 | D10: HF555357253 | E10: United Healthcare | F10: United Healthcare | G10: No Payer | H10: 46156 | I10: 99494 | J10: BH | K10: =H10+M10 | L10: =K10-TODAY() | M10: 90 | N10: UHC COMMERCIAL | S10: 1 | T10: 396.27 | U10: 0 | V10: 0 | W10: 396.27 | X10: 86 | Y10: MEARS, CHAD | Z10: ASAP - DEER VALLEY | AB10: 46180 | AD10: F4320
C11: 558887755 | D11: HF475049197 | E11: Allwell - All States (Centene) | F11: Allwell - All States (Centene) | G11: Arizona Complete Health (Centene) | H11: 46153 | I11: 99493 | J11: BH | K11: =H11+M11 | L11: =K11-TODAY() | M11: 95 | N11: WELLCARE BY ALLWELL | S11: 1 | T11: 976.64 | U11: 0 | V11: 0 | W11: 976.64 | X11: 89 | Y11: SARKAR, AWNIK | Z11: ASAP Peoria | AB11: 46180 | AD11: F4320
C12: 559931934 | D12: HF494160468 | E12: UnitedHealthcare Community Plan / Arizona Long Term Care | F12: UnitedHealthcare Community Plan / Arizona Long Term Care | G12: No Payer | H12: 46162 | I12: 99494 | J12: BH | K12: =H12+M12 | L12: =K12-TODAY() | M12: 90 | N12: UHC COMMUNITY | S12: 1 | T12: 396.27 | U12: 0 | V12: 0 | W12: 396.27 | X12: 80 | Y12: O'NEIL, ROY | Z12: ASAP - DEER VALLEY | AB12: 46182 | AC12: 46196 | AD12: F32A | AE12: F411
C13: 559931934 | D13: HF494160468 | E13: UnitedHealthcare Community Plan / Arizona Long Term Care | F13: UnitedHealthcare Community Plan / Arizona Long Term Care | G13: No Payer | H13: 46162 | I13: 99494 | J13: BH | K13: =H13+M13 | L13: =K13-TODAY() | M13: 90 | N13: UHC COMMUNITY | S13: 1 | T13: 396.27 | U13: 0 | V13: 0 | W13: 396.27 | X13: 80 | Y13: O'NEIL, ROY | Z13: ASAP - DEER VALLEY | AB13: 46182 | AC13: 46196 | AD13: F32A | AE13: F411
C14: 560175340 | D14: HF485806241 | E14: UnitedHealthcare Community Plan / Arizona Long Term Care | F14: UnitedHealthcare Community Plan / Arizona Long Term Care | G14: UnitedHealthcare Community Plan / Arizona Long Term Care | H14: 46162 | I14: 99494 | J14: BH | K14: =H14+M14 | L14: =K14-TODAY() | M14: 90 | N14: UHC COMMUNITY | S14: 1 | T14: 396.27 | U14: 0 | V14: 0 | W14: 396.27 | X14: 80 | Y14: TURLEY, TODD | Z14: ASAP - DEER VALLEY | AB14: 46182 | AC14: 46195 | AD14: F1190 | AE14: F32A
C15: 560027331 | D15: HF495815066 | E15: United Healthcare | F15: United Healthcare | G15: No Payer | H15: 46164 | I15: 99492 | J15: BH | K15: =H15+M15 | L15: =K15-TODAY() | M15: 90 | N15: UHC COMMERCIAL | S15: 1 | T15: 1029.98 | U15: 0 | V15: 0 | W15: 1029.98 | X15: 78 | Y15: MORALES, DAVID | Z15: ASAP - Gilbert | AB15: 46182 | AD15: F39
C16: 560027331 | D16: HF495815066 | E16: United Healthcare | F16: United Healthcare | G16: No Payer | H16: 46164 | I16: 99494 | J16: BH | K16: =H16+M16 | L16: =K16-TODAY() | M16: 90 | N16: UHC COMMERCIAL | S16: 1 | T16: 396.27 | U16: 0 | V16: 0 | W16: 396.27 | X16: 78 | Y16: MORALES, DAVID | Z16: ASAP - Gilbert | AB16: 46182 | AD16: F39
C17: 560178463 | D17: HF528535429 | E17: UnitedHealthcare Community Plan / Arizona Long Term Care | F17: UnitedHealthcare Community Plan / Arizona Long Term Care | G17: Mercy Care RBHA | H17: 46164 | I17: 99493 | J17: BH | K17: =H17+M17 | L17: =K17-TODAY() | M17: 90 | N17: UHC COMMUNITY | S17: 1 | T17: 976.64 | U17: 0 | V17: 0 | W17: 976.64 | X17: 78 | Y17: MEARS, CHAD | Z17: ASAP - DEER VALLEY | AB17: 46181 | AC17: 46189 | AD17: F331 | AE17: F411
C18: 560178463 | D18: HF528535429 | E18: UnitedHealthcare Community Plan / Arizona Long Term Care | F18: UnitedHealthcare Community Plan / Arizona Long Term Care | G18: Mercy Care RBHA | H18: 46164 | I18: 99494 | J18: BH | K18: =H18+M18 | L18: =K18-TODAY() | M18: 90 | N18: UHC COMMUNITY | S18: 1 | T18: 396.27 | U18: 0 | V18: 0 | W18: 396.27 | X18: 78 | Y18: MEARS, CHAD | Z18: ASAP - DEER VALLEY | AB18: 46181 | AC18: 46189 | AD18: F331 | AE18: F411

Sheet DME
A1: Durable Medical Equipment (DME) - timely filing 10 day watchlist
A2: Claims whose primary payer timely filing deadline falls within 10 days of 10 August 2026. Fill in the amber Claim Status and Notes columns - they feed the All Claims tab automatically. Every other column is copied from the source file or calculated.
A4: Claim Status | B4: Notes | C4: Primary Claim ID | D4: Chart Number | E4: Responsible Payer | F4: Primary Payer Name | G4: Secondary Payer Name | H4: Date of Service | I4: Procedure Code | J4: Specialty | K4: Filing Deadline | L4: Days Until Deadline | M4: Timely Filing Limit (Days) | N4: Reference Carrier | O4: Limit Basis / Caveat | P4: Modifier 1 | Q4: Modifier 2 | R4: Modifier 3 | S4: Units | T4: Charge Amount | U4: Insurance Payment | V4: Adjustment | W4: Insurance Balance | X4: AR Age by Service Date | Y4: Rendering Provider | Z4: Location Name | AA4: Secondary Claim ID | AB4: Created Date | AC4: Insurance Check Date | AD4: Diagnosis Code 1 | AE4: Diagnosis Code 2 | AF4: Diagnosis Code 3 | AG4: Diagnosis Code 4
C5: 559604554 | D5: HF549730183 | E5: Optum Care Medical Network of Arizona, Utah, & Washington (LifePrint) | F5: Optum Care Medical Network of Arizona, Utah, & Washington (LifePrint) | G5: LIEN 03 | H5: 46157 | I5: A6023 | J5: DME | K5: =H5+M5 | L5: =K5-TODAY() | M5: 90 | N5: OPTUM | P5: A1 | S5: 20 | T5: 36353.8 | U5: 0 | V5: 0 | W5: 36353.8 | X5: 85 | Y5: MCCUNNIFF, PETER | Z5: ASAP Peoria | AB5: 46217 | AD5: G894 | AE5: M50022 | AF5: M50023 | AG5: M50122
C6: 561880042 | D6: HF545888888 | E6: Humana Gold Plus HMO | F6: Humana Gold Plus HMO | G6: No Payer | H6: 46160 | I6: A6023 | J6: DME | K6: =H6+M6 | L6: =K6-TODAY() | M6: 90 | N6: HUMANA MA | O6: ASSUMPTION - shorter of two limits used. 180 days for physicians, 90 for ancillary providers; confirm the provider category. | P6: A2 | S6: 40 | T6: 72707.6 | U6: 0 | V6: 0 | W6: 72707.6 | X6: 82 | Y6: Van Dyke, Sandra | Z6: ASAP - Gilbert | AB6: 46183 | AC6: 46185 | AD6: G894 | AE6: G90523
C7: 559742691 | D7: HF543653317 | E7: Optum Care Medical Network of Arizona, Utah, & Washington (LifePrint) | F7: Optum Care Medical Network of Arizona, Utah, & Washington (LifePrint) | G7: No Payer | H7: 46160 | I7: A6010 | J7: DME | K7: =H7+M7 | L7: =K7-TODAY() | M7: 90 | N7: OPTUM | P7: A2 | S7: 20 | T7: 5916.4 | U7: 0 | V7: 0 | W7: 5916.4 | X7: 82 | Y7: TONDINI, JENISE | Z7: ASAP - Goodyear | AB7: 46162 | AC7: 46196 | AD7: G894
C8: 561237046 | D8: HF533960930 | E8: UnitedHealthcare Community Plan / Arizona Long Term Care | F8: UnitedHealthcare Community Plan / Arizona Long Term Care | G8: Molina Complete Care of Arizona (Magellan Complete Care AZ) | H8: 46163 | I8: A6010 | J8: DME | K8: =H8+M8 | L8: =K8-TODAY() | M8: 90 | N8: UHC COMMUNITY | P8: A1 | S8: 10 | T8: 2958.2 | U8: 0 | V8: 0 | W8: 2958.2 | X8: 79 | Y8: LUKE, TIMOTHY | Z8: ASAP - DEER VALLEY | AB8: 46177 | AC8: 46183 | AD8: M5030 | AE8: M5412
C9: 561851402 | D9: HF508345961 | E9: Optum Care Medical Network of Arizona, Utah, & Washington (LifePrint) | F9: Optum Care Medical Network of Arizona, Utah, & Washington (LifePrint) | G9: No Payer | H9: 46164 | I9: A6010 | J9: DME | K9: =H9+M9 | L9: =K9-TODAY() | M9: 90 | N9: OPTUM | P9: A1 | S9: 20 | T9: 36353.8 | U9: 0 | V9: 0 | W9: 36353.8 | X9: 78 | Y9: CURRIE, DAVID | Z9: ASAP - Gilbert | AB9: 46183 | AC9: 46194 | AD9: G894 | AE9: M461

Sheet GAE
A1: Genicular Artery Embolization (GAE) - timely filing 10 day watchlist
A2: Claims whose primary payer timely filing deadline falls within 10 days of 10 August 2026. Fill in the amber Claim Status and Notes columns - they feed the All Claims tab automatically. Every other column is copied from the source file or calculated.
A4: Claim Status | B4: Notes | C4: Primary Claim ID | D4: Chart Number | E4: Responsible Payer | F4: Primary Payer Name | G4: Secondary Payer Name | H4: Date of Service | I4: Procedure Code | J4: Specialty | K4: Filing Deadline | L4: Days Until Deadline | M4: Timely Filing Limit (Days) | N4: Reference Carrier | O4: Limit Basis / Caveat | P4: Modifier 1 | Q4: Modifier 2 | R4: Modifier 3 | S4: Units | T4: Charge Amount | U4: Insurance Payment | V4: Adjustment | W4: Insurance Balance | X4: AR Age by Service Date | Y4: Rendering Provider | Z4: Location Name | AA4: Secondary Claim ID | AB4: Created Date | AC4: Insurance Check Date | AD4: Diagnosis Code 1 | AE4: Diagnosis Code 2 | AF4: Diagnosis Code 3 | AG4: Diagnosis Code 4
A5: No claims for this specialty fall within the 10 day window as of 08/10/2026.

Sheet ORTHO
A1: Orthopedic (ORTHO) - timely filing 10 day watchlist
A2: Claims whose primary payer timely filing deadline falls within 10 days of 10 August 2026. Fill in the amber Claim Status and Notes columns - they feed the All Claims tab automatically. Every other column is copied from the source file or calculated.
A4: Claim Status | B4: Notes | C4: Primary Claim ID | D4: Chart Number | E4: Responsible Payer | F4: Primary Payer Name | G4: Secondary Payer Name | H4: Date of Service | I4: Procedure Code | J4: Specialty | K4: Filing Deadline | L4: Days Until Deadline | M4: Timely Filing Limit (Days) | N4: Reference Carrier | O4: Limit Basis / Caveat | P4: Modifier 1 | Q4: Modifier 2 | R4: Modifier 3 | S4: Units | T4: Charge Amount | U4: Insurance Payment | V4: Adjustment | W4: Insurance Balance | X4: AR Age by Service Date | Y4: Rendering Provider | Z4: Location Name | AA4: Secondary Claim ID | AB4: Created Date | AC4: Insurance Check Date | AD4: Diagnosis Code 1 | AE4: Diagnosis Code 2 | AF4: Diagnosis Code 3 | AG4: Diagnosis Code 4
C5: 559605223 | D5: HF549730183 | E5: Optum Care Medical Network of Arizona, Utah, & Washington (LifePrint) | F5: Optum Care Medical Network of Arizona, Utah, & Washington (LifePrint) | G5: No Payer | H5: 46155 | I5: 22551 | J5: ORTHO | K5: =H5+M5 | L5: =K5-TODAY() | M5: 90 | N5: OPTUM | S5: 1 | T5: 11690.98 | U5: 0 | V5: 0 | W5: 11690.98 | X5: 87 | Y5: BURGHER, ABRAM | Z5: ASAP Surgery Centers North Valley LLC | AB5: 46161 | AD5: M50022 | AE5: M50122 | AF5: M5412 | AG5: M5000
C6: 559605223 | D6: HF549730183 | E6: Optum Care Medical Network of Arizona, Utah, & Washington (LifePrint) | F6: Optum Care Medical Network of Arizona, Utah, & Washington (LifePrint) | G6: No Payer | H6: 46155 | I6: 22845 | J6: ORTHO | K6: =H6+M6 | L6: =K6-TODAY() | M6: 90 | N6: OPTUM | P6: 59 | S6: 1 | T6: 4951.24 | U6: 0 | V6: 0 | W6: 4951.24 | X6: 87 | Y6: BURGHER, ABRAM | Z6: ASAP Surgery Centers North Valley LLC | AB6: 46161 | AD6: M50022 | AE6: M50023 | AF6: M50122 | AG6: M5412
C7: 559605223 | D7: HF549730183 | E7: Optum Care Medical Network of Arizona, Utah, & Washington (LifePrint) | F7: Optum Care Medical Network of Arizona, Utah, & Washington (LifePrint) | G7: No Payer | H7: 46155 | I7: 22853 | J7: ORTHO | K7: =H7+M7 | L7: =K7-TODAY() | M7: 90 | N7: OPTUM | S7: 1 | T7: 1758.12 | U7: 0 | V7: 0 | W7: 1758.12 | X7: 87 | Y7: BURGHER, ABRAM | Z7: ASAP Surgery Centers North Valley LLC | AB7: 46161 | AD7: M50022 | AE7: M50122 | AF7: M5412 | AG7: M5000
C8: 559605223 | D8: HF549730183 | E8: Optum Care Medical Network of Arizona, Utah, & Washington (LifePrint) | F8: Optum Care Medical Network of Arizona, Utah, & Washington (LifePrint) | G8: No Payer | H8: 46155 | I8: 22853 | J8: ORTHO | K8: =H8+M8 | L8: =K8-TODAY() | M8: 90 | N8: OPTUM | P8: 59 | S8: 1 | T8: 1758.12 | U8: 0 | V8: 0 | W8: 1758.12 | X8: 87 | Y8: BURGHER, ABRAM | Z8: ASAP Surgery Centers North Valley LLC | AB8: 46161 | AD8: M50023 | AE8: M5412 | AF8: M5000 | AG8: M542
C9: 559356030 | D9: HF427171307 | E9: HealthSpring Medicare Advantage | F9: HealthSpring Medicare Advantage | G9: No Payer | H9: 46156 | I9: 63047 | J9: ORTHO | K9: =H9+M9 | L9: =K9-TODAY() | M9: 90 | N9: CIGNA / CIGNA MEDICARE | S9: 1 | T9: 7623.07 | U9: 0 | V9: 0 | W9: 7623.07 | X9: 86 | Y9: KRAUSE, JEFFREY | Z9: ASAP Surgery Centers North Valley LLC | AB9: 46160 | AC9: 46170 | AD9: M48062
C10: 565931559 | D10: HF549060053 | E10: Devoted Health Plan | F10: Devoted Health Plan | G10: No Payer | H10: 46190 | I10: 63047 | J10: ORTHO | K10: =H10+M10 | L10: =K10-TODAY() | M10: 60 | N10: DEVOTED | O10: Shortest limit on the reference list. | S10: 1 | T10: 7623.07 | U10: 0 | V10: 0 | W10: 7623.07 | X10: 52 | Y10: MAYURAN, VIKRAM | Z10: ASAP Surgery Centers North Valley LLC | AB10: 46210 | AD10: M48062
C11: 565931559 | D11: HF549060053 | E11: Devoted Health Plan | F11: Devoted Health Plan | G11: No Payer | H11: 46190 | I11: 63048 | J11: ORTHO | K11: =H11+M11 | L11: =K11-TODAY() | M11: 60 | N11: DEVOTED | O11: Shortest limit on the reference list. | S11: 1 | T11: 1433.32 | U11: 0 | V11: 0 | W11: 1433.32 | X11: 52 | Y11: MAYURAN, VIKRAM | Z11: ASAP Surgery Centers North Valley LLC | AB11: 46210 | AD11: M48062
C12: 561233259 | D12: WC-509516716 | E12: United Healthcare | F12: United Healthcare | G12: No Payer | H12: 46160 | I12: 63047 | J12: ORTHO | K12: =H12+M12 | L12: =K12-TODAY() | M12: 90 | N12: UHC COMMERCIAL | S12: 1 | T12: 7623.07 | U12: 0 | V12: 0 | W12: 7623.07 | X12: 82 | Y12: MAYURAN, VIKRAM | Z12: ASAP Surgery Centers North Valley LLC | AB12: 46177 | AD12: M5416 | AE12: M48061 | AF12: S335XXA
C13: 561233259 | D13: WC-509516716 | E13: United Healthcare | F13: United Healthcare | G13: No Payer | H13: 46160 | I13: 63048 | J13: ORTHO | K13: =H13+M13 | L13: =K13-TODAY() | M13: 90 | N13: UHC COMMERCIAL | S13: 1 | T13: 1433.32 | U13: 0 | V13: 0 | W13: 1433.32 | X13: 82 | Y13: MAYURAN, VIKRAM | Z13: ASAP Surgery Centers North Valley LLC | AB13: 46177 | AD13: M5416 | AE13: M48061 | AF13: S335XXA
C14: 559340087 | D14: HF522538764 | E14: Allwell - All States (Centene) | F14: Allwell - All States (Centene) | G14: No Payer | H14: 46157 | I14: 63685 | J14: ORTHO | K14: =H14+M14 | L14: =K14-TODAY() | M14: 95 | N14: WELLCARE BY ALLWELL | S14: 1 | T14: 2493.33 | U14: 0 | V14: 0 | W14: 2493.33 | X14: 85 | Y14: O'NEIL, ROY | Z14: ASAP Surgery Centers North Valley LLC | AB14: 46160 | AC14: 46170 | AD14: M961 | AE14: M5416 | AF14: G894
C15: 561246589 | D15: HF554018380 | E15: UnitedHealthcare Community Plan / Arizona Long Term Care | F15: UnitedHealthcare Community Plan / Arizona Long Term Care | G15: No Payer | H15: 46163 | I15: 63030 | J15: ORTHO | K15: =H15+M15 | L15: =K15-TODAY() | M15: 90 | N15: UHC COMMUNITY | P15: RT | S15: 1 | T15: 6297.27 | U15: 0 | V15: 0 | W15: 6297.27 | X15: 79 | Y15: LUKE, TIMOTHY | Z15: ASAP Surgery Centers North Valley LLC | AB15: 46177 | AC15: 46183 | AD15: M4807 | AE15: M5417 | AF15: M5127

Sheet US
A1: Ultrasound (US) - timely filing 10 day watchlist
A2: Claims whose primary payer timely filing deadline falls within 10 days of 10 August 2026. Fill in the amber Claim Status and Notes columns - they feed the All Claims tab automatically. Every other column is copied from the source file or calculated.
A4: Claim Status | B4: Notes | C4: Primary Claim ID | D4: Chart Number | E4: Responsible Payer | F4: Primary Payer Name | G4: Secondary Payer Name | H4: Date of Service | I4: Procedure Code | J4: Specialty | K4: Filing Deadline | L4: Days Until Deadline | M4: Timely Filing Limit (Days) | N4: Reference Carrier | O4: Limit Basis / Caveat | P4: Modifier 1 | Q4: Modifier 2 | R4: Modifier 3 | S4: Units | T4: Charge Amount | U4: Insurance Payment | V4: Adjustment | W4: Insurance Balance | X4: AR Age by Service Date | Y4: Rendering Provider | Z4: Location Name | AA4: Secondary Claim ID | AB4: Created Date | AC4: Insurance Check Date | AD4: Diagnosis Code 1 | AE4: Diagnosis Code 2 | AF4: Diagnosis Code 3 | AG4: Diagnosis Code 4
C5: 563065806 | D5: HF550504744 | E5: Devoted Health Plan | F5: Devoted Health Plan | G5: No Payer | H5: 46184 | I5: 93923 | J5: US | K5: =H5+M5 | L5: =K5-TODAY() | M5: 60 | N5: DEVOTED | O5: Shortest limit on the reference list. | S5: 1 | T5: 879.06 | U5: 0 | V5: 0 | W5: 879.06 | X5: 58 | Y5: TURLEY, TODD | Z5: ASAP - DEER VALLEY 240 | AB5: 46195 | AC5: 46202 | AD5: G5790 | AE5: M5459 | AF5: M546 | AG5: N39498
C6: 563065806 | D6: HF550504744 | E6: Devoted Health Plan | F6: Devoted Health Plan | G6: No Payer | H6: 46184 | I6: 93925 | J6: US | K6: =H6+M6 | L6: =K6-TODAY() | M6: 60 | N6: DEVOTED | O6: Shortest limit on the reference list. | S6: 1 | T6: 1649.2 | U6: 0 | V6: 0 | W6: 1649.2 | X6: 58 | Y6: TURLEY, TODD | Z6: ASAP - DEER VALLEY 240 | AB6: 46195 | AC6: 46202 | AD6: G5790 | AE6: M5459 | AF6: M546 | AG6: N39498
C7: 563065806 | D7: HF550504744 | E7: Devoted Health Plan | F7: Devoted Health Plan | G7: No Payer | H7: 46184 | I7: 93970 | J7: US | K7: =H7+M7 | L7: =K7-TODAY() | M7: 60 | N7: DEVOTED | O7: Shortest limit on the reference list. | S7: 1 | T7: 1294.23 | U7: 0 | V7: 0 | W7: 1294.23 | X7: 58 | Y7: TURLEY, TODD | Z7: ASAP - DEER VALLEY 240 | AB7: 46195 | AC7: 46202 | AD7: G5790 | AE7: M5459 | AF7: M546 | AG7: N39498
C8: 567453889 | D8: HF533821631 | E8: HealthSpring Medicare Advantage | F8: HealthSpring Medicare Advantage | G8: No Payer | H8: 46154 | I8: 93923 | J8: US | K8: =H8+M8 | L8: =K8-TODAY() | M8: 90 | N8: CIGNA / CIGNA MEDICARE | S8: 1 | T8: 879.06 | U8: 0 | V8: 0 | W8: 879.06 | X8: 88 | Y8: LEATHEM, JARRETT | Z8: ASAP - Gilbert | AB8: 46164 | AC8: 46170 | AD8: I8393 | AE8: I872
C9: 567453889 | D9: HF533821631 | E9: HealthSpring Medicare Advantage | F9: HealthSpring Medicare Advantage | G9: No Payer | H9: 46154 | I9: 93925 | J9: US | K9: =H9+M9 | L9: =K9-TODAY() | M9: 90 | N9: CIGNA / CIGNA MEDICARE | S9: 1 | T9: 1649.2 | U9: 0 | V9: 0 | W9: 1649.2 | X9: 88 | Y9: LEATHEM, JARRETT | Z9: ASAP - Gilbert | AB9: 46164 | AC9: 46170 | AD9: I8393 | AE9: I872
C10: 560081393 | D10: HF544192008 | E10: United Healthcare | F10: United Healthcare | G10: No Payer | H10: 46155 | I10: 93923 | J10: US | K10: =H10+M10 | L10: =K10-TODAY() | M10: 90 | N10: UHC COMMERCIAL | S10: 1 | T10: 879.06 | U10: 0 | V10: 0 | W10: 879.06 | X10: 87 | Y10: BURGHER, ABRAM | Z10: ASAP - Surprise - Reems | AB10: 46164 | AC10: 46175 | AD10: I739 | AE10: M79604 | AF10: M79605
C11: 560081393 | D11: HF544192008 | E11: United Healthcare | F11: United Healthcare | G11: No Payer | H11: 46155 | I11: 93925 | J11: US | K11: =H11+M11 | L11: =K11-TODAY() | M11: 90 | N11: UHC COMMERCIAL | S11: 1 | T11: 1649.2 | U11: 0 | V11: 0 | W11: 1649.2 | X11: 87 | Y11: BURGHER, ABRAM | Z11: ASAP - Surprise - Reems | AB11: 46164 | AC11: 46175 | AD11: I739 | AE11: M79604 | AF11: M79605
C12: 560081393 | D12: HF544192008 | E12: United Healthcare | F12: United Healthcare | G12: No Payer | H12: 46155 | I12: 93970 | J12: US | K12: =H12+M12 | L12: =K12-TODAY() | M12: 90 | N12: UHC COMMERCIAL | S12: 1 | T12: 1294.23 | U12: 0 | V12: 0 | W12: 1294.23 | X12: 87 | Y12: BURGHER, ABRAM | Z12: ASAP - Surprise - Reems | AB12: 46164 | AC12: 46175 | AD12: I739 | AE12: M79604 | AF12: M79605
C13: 558639899 | D13: HF523293759 | E13: Banner Health & Aetna Health Insurance Company | F13: Banner Health & Aetna Health Insurance Company | G13: No Payer | H13: 46126 | I13: 93923 | J13: US | K13: =H13+M13 | L13: =K13-TODAY() | M13: 120 | N13: BANNER HEALTH & AETNA | S13: 1 | T13: 879.06 | U13: 0 | V13: 0 | W13: 879.06 | X13: 116 | Y13: LEATHEM, JARRETT | Z13: ASAP - Gilbert | AB13: 46141 | AD13: M1712 | AE13: M25562 | AF13: I872
C14: 560709048 | D14: HF330335441 | E14: HealthSpring Medicare Advantage | F14: HealthSpring Medicare Advantage | G14: No Payer | H14: 46163 | I14: 93923 | J14: US | K14: =H14+M14 | L14: =K14-TODAY() | M14: 90 | N14: CIGNA / CIGNA MEDICARE | S14: 1 | T14: 879.06 | U14: 0 | V14: 0 | W14: 879.06 | X14: 79 | Y14: TURLEY, TODD | Z14: ASAP - DEER VALLEY 240 | AB14: 46171 | AC14: 46182 | AD14: R2243
C15: 560709048 | D15: HF330335441 | E15: HealthSpring Medicare Advantage | F15: HealthSpring Medicare Advantage | G15: No Payer | H15: 46163 | I15: 93925 | J15: US | K15: =H15+M15 | L15: =K15-TODAY() | M15: 90 | N15: CIGNA / CIGNA MEDICARE | S15: 1 | T15: 1649.2 | U15: 0 | V15: 0 | W15: 1649.2 | X15: 79 | Y15: TURLEY, TODD | Z15: ASAP - DEER VALLEY 240 | AB15: 46171 | AC15: 46182 | AD15: R2243
C16: 560710074 | D16: HF556870121 | E16: United Healthcare | F16: United Healthcare | G16: No Payer | H16: 46163 | I16: 93923 | J16: US | K16: =H16+M16 | L16: =K16-TODAY() | M16: 90 | N16: UHC COMMERCIAL | S16: 1 | T16: 879.06 | U16: 0 | V16: 0 | W16: 879.06 | X16: 79 | Y16: TURLEY, TODD | Z16: ASAP - DEER VALLEY 240 | AB16: 46171 | AD16: R2242
C17: 560710074 | D17: HF556870121 | E17: United Healthcare | F17: United Healthcare | G17: No Payer | H17: 46163 | I17: 93925 | J17: US | K17: =H17+M17 | L17: =K17-TODAY() | M17: 90 | N17: UHC COMMERCIAL | S17: 1 | T17: 1649.2 | U17: 0 | V17: 0 | W17: 1649.2 | X17: 79 | Y17: TURLEY, TODD | Z17: ASAP - DEER VALLEY 240 | AB17: 46171 | AD17: R2242
C18: 560710074 | D18: HF556870121 | E18: United Healthcare | F18: United Healthcare | G18: No Payer | H18: 46163 | I18: 93970 | J18: US | K18: =H18+M18 | L18: =K18-TODAY() | M18: 90 | N18: UHC COMMERCIAL | S18: 1 | T18: 1294.23 | U18: 0 | V18: 0 | W18: 1294.23 | X18: 79 | Y18: TURLEY, TODD | Z18: ASAP - DEER VALLEY 240 | AB18: 46171 | AD18: R2242
C19: 566566596 | D19: HF452713382 | E19: UnitedHealthcare Community Plan / Arizona Long Term Care | F19: UnitedHealthcare Community Plan / Arizona Long Term Care | G19: No Payer | H19: 46163 | I19: 93923 | J19: US | K19: =H19+M19 | L19: =K19-TODAY() | M19: 90 | N19: UHC COMMUNITY | S19: 1 | T19: 879.06 | U19: 0 | V19: 0 | W19: 879.06 | X19: 79 | Y19: TURLEY, TODD | Z19: ASAP - DEER VALLEY 240 | AB19: 46171 | AC19: 46182 | AD19: I872 | AE19: I739
C20: 566566596 | D20: HF452713382 | E20: UnitedHealthcare Community Plan / Arizona Long Term Care | F20: UnitedHealthcare Community Plan / Arizona Long Term Care | G20: No Payer | H20: 46163 | I20: 93925 | J20: US | K20: =H20+M20 | L20: =K20-TODAY() | M20: 90 | N20: UHC COMMUNITY | S20: 1 | T20: 1649.2 | U20: 0 | V20: 0 | W20: 1649.2 | X20: 79 | Y20: TURLEY, TODD | Z20: ASAP - DEER VALLEY 240 | AB20: 46171 | AC20: 46182 | AD20: I872 | AE20: I739
C21: 566566596 | D21: HF452713382 | E21: UnitedHealthcare Community Plan / Arizona Long Term Care | F21: UnitedHealthcare Community Plan / Arizona Long Term Care | G21: No Payer | H21: 46163 | I21: 93970 | J21: US | K21: =H21+M21 | L21: =K21-TODAY() | M21: 90 | N21: UHC COMMUNITY | S21: 1 | T21: 1294.23 | U21: 0 | V21: 0 | W21: 1294.23 | X21: 79 | Y21: TURLEY, TODD | Z21: ASAP - DEER VALLEY 240 | AB21: 46171 | AC21: 46182 | AD21: I872 | AE21: I739

Sheet All Claims
A1: All specialties - timely filing 10 day watchlist
A2: Every claim from the five specialty tabs in one list, as of 10 August 2026. Claim Status and Notes are live links to the specialty tabs - edit them there, not here.
A4: Claim Status | B4: Notes | C4: Primary Claim ID | D4: Chart Number | E4: Responsible Payer | F4: Primary Payer Name | G4: Secondary Payer Name | H4: Date of Service | I4: Procedure Code | J4: Specialty | K4: Filing Deadline | L4: Days Until Deadline | M4: Timely Filing Limit (Days) | N4: Reference Carrier | O4: Limit Basis / Caveat | P4: Modifier 1 | Q4: Modifier 2 | R4: Modifier 3 | S4: Units | T4: Charge Amount | U4: Insurance Payment | V4: Adjustment | W4: Insurance Balance | X4: AR Age by Service Date | Y4: Rendering Provider | Z4: Location Name | AA4: Secondary Claim ID | AB4: Created Date | AC4: Insurance Check Date | AD4: Diagnosis Code 1 | AE4: Diagnosis Code 2 | AF4: Diagnosis Code 3 | AG4: Diagnosis Code 4 | AH4: Linked Cell (Status / Notes)
A5: =IF('BH'!A5="","",'BH'!A5) | B5: =IF('BH'!B5="","",'BH'!B5) | C5: 559340053 | D5: HF458717535 | E5: Blue Cross Blue Shield of Arizona (BCBS AZ) | F5: Blue Cross Blue Shield of Arizona (BCBS AZ) | G5: No Payer | H5: 46154 | I5: 99492 | J5: BH | K5: =H5+M5 | L5: =K5-TODAY() | M5: 90 | N5: BCBS | O5: Limit cut from 365 to 90 days effective 01/01/2026; 90 applies because the date of service is in 2026. | S5: 1 | T5: 1029.98 | U5: 0 | V5: 0 | W5: 826.36 | X5: 88 | Y5: SARKAR, AWNIK | Z5: ASAP Peoria | AB5: 46180 | AC5: 46216 | AD5: F4320 | AH5: BH!A5 / BH!B5
A6: =IF('BH'!A6="","",'BH'!A6) | B6: =IF('BH'!B6="","",'BH'!B6) | C6: 559340053 | D6: HF458717535 | E6: Blue Cross Blue Shield of Arizona (BCBS AZ) | F6: Blue Cross Blue Shield of Arizona (BCBS AZ) | G6: No Payer | H6: 46154 | I6: 99494 | J6: BH | K6: =H6+M6 | L6: =K6-TODAY() | M6: 90 | N6: BCBS | O6: Limit cut from 365 to 90 days effective 01/01/2026; 90 applies because the date of service is in 2026. | S6: 1 | T6: 396.27 | U6: 0 | V6: 0 | W6: 317.94 | X6: 88 | Y6: SARKAR, AWNIK | Z6: ASAP Peoria | AB6: 46180 | AC6: 46216 | AD6: F4320 | AH6: BH!A6 / BH!B6
A7: =IF('US'!A5="","",'US'!A5) | B7: =IF('US'!B5="","",'US'!B5) | C7: 563065806 | D7: HF550504744 | E7: Devoted Health Plan | F7: Devoted Health Plan | G7: No Payer | H7: 46184 | I7: 93923 | J7: US | K7: =H7+M7 | L7: =K7-TODAY() | M7: 60 | N7: DEVOTED | O7: Shortest limit on the reference list. | S7: 1 | T7: 879.06 | U7: 0 | V7: 0 | W7: 879.06 | X7: 58 | Y7: TURLEY, TODD | Z7: ASAP - DEER VALLEY 240 | AB7: 46195 | AC7: 46202 | AD7: G5790 | AE7: M5459 | AF7: M546 | AG7: N39498 | AH7: US!A5 / US!B5
A8: =IF('US'!A6="","",'US'!A6) | B8: =IF('US'!B6="","",'US'!B6) | C8: 563065806 | D8: HF550504744 | E8: Devoted Health Plan | F8: Devoted Health Plan | G8: No Payer | H8: 46184 | I8: 93925 | J8: US | K8: =H8+M8 | L8: =K8-TODAY() | M8: 60 | N8: DEVOTED | O8: Shortest limit on the reference list. | S8: 1 | T8: 1649.2 | U8: 0 | V8: 0 | W8: 1649.2 | X8: 58 | Y8: TURLEY, TODD | Z8: ASAP - DEER VALLEY 240 | AB8: 46195 | AC8: 46202 | AD8: G5790 | AE8: M5459 | AF8: M546 | AG8: N39498 | AH8: US!A6 / US!B6
A9: =IF('US'!A7="","",'US'!A7) | B9: =IF('US'!B7="","",'US'!B7) | C9: 563065806 | D9: HF550504744 | E9: Devoted Health Plan | F9: Devoted Health Plan | G9: No Payer | H9: 46184 | I9: 93970 | J9: US | K9: =H9+M9 | L9: =K9-TODAY() | M9: 60 | N9: DEVOTED | O9: Shortest limit on the reference list. | S9: 1 | T9: 1294.23 | U9: 0 | V9: 0 | W9: 1294.23 | X9: 58 | Y9: TURLEY, TODD | Z9: ASAP - DEER VALLEY 240 | AB9: 46195 | AC9: 46202 | AD9: G5790 | AE9: M5459 | AF9: M546 | AG9: N39498 | AH9: US!A7 / US!B7
A10: =IF('US'!A8="","",'US'!A8) | B10: =IF('US'!B8="","",'US'!B8) | C10: 567453889 | D10: HF533821631 | E10: HealthSpring Medicare Advantage | F10: HealthSpring Medicare Advantage | G10: No Payer | H10: 46154 | I10: 93923 | J10: US | K10: =H10+M10 | L10: =K10-TODAY() | M10: 90 | N10: CIGNA / CIGNA MEDICARE | S10: 1 | T10: 879.06 | U10: 0 | V10: 0 | W10: 879.06 | X10: 88 | Y10: LEATHEM, JARRETT | Z10: ASAP - Gilbert | AB10: 46164 | AC10: 46170 | AD10: I8393 | AE10: I872 | AH10: US!A8 / US!B8
A11: =IF('US'!A9="","",'US'!A9) | B11: =IF('US'!B9="","",'US'!B9) | C11: 567453889 | D11: HF533821631 | E11: HealthSpring Medicare Advantage | F11: HealthSpring Medicare Advantage | G11: No Payer | H11: 46154 | I11: 93925 | J11: US | K11: =H11+M11 | L11: =K11-TODAY() | M11: 90 | N11: CIGNA / CIGNA MEDICARE | S11: 1 | T11: 1649.2 | U11: 0 | V11: 0 | W11: 1649.2 | X11: 88 | Y11: LEATHEM, JARRETT | Z11: ASAP - Gilbert | AB11: 46164 | AC11: 46170 | AD11: I8393 | AE11: I872 | AH11: US!A9 / US!B9
A12: =IF('ORTHO'!A5="","",'ORTHO'!A5) | B12: =IF('ORTHO'!B5="","",'ORTHO'!B5) | C12: 559605223 | D12: HF549730183 | E12: Optum Care Medical Network of Arizona, Utah, & Washington (LifePrint) | F12: Optum Care Medical Network of Arizona, Utah, & Washington (LifePrint) | G12: No Payer | H12: 46155 | I12: 22551 | J12: ORTHO | K12: =H12+M12 | L12: =K12-TODAY() | M12: 90 | N12: OPTUM | S12: 1 | T12: 11690.98 | U12: 0 | V12: 0 | W12: 11690.98 | X12: 87 | Y12: BURGHER, ABRAM | Z12: ASAP Surgery Centers North Valley LLC | AB12: 46161 | AD12: M50022 | AE12: M50122 | AF12: M5412 | AG12: M5000 | AH12: ORTHO!A5 / ORTHO!B5
A13: =IF('ORTHO'!A6="","",'ORTHO'!A6) | B13: =IF('ORTHO'!B6="","",'ORTHO'!B6) | C13: 559605223 | D13: HF549730183 | E13: Optum Care Medical Network of Arizona, Utah, & Washington (LifePrint) | F13: Optum Care Medical Network of Arizona, Utah, & Washington (LifePrint) | G13: No Payer | H13: 46155 | I13: 22845 | J13: ORTHO | K13: =H13+M13 | L13: =K13-TODAY() | M13: 90 | N13: OPTUM | P13: 59 | S13: 1 | T13: 4951.24 | U13: 0 | V13: 0 | W13: 4951.24 | X13: 87 | Y13: BURGHER, ABRAM | Z13: ASAP Surgery Centers North Valley LLC | AB13: 46161 | AD13: M50022 | AE13: M50023 | AF13: M50122 | AG13: M5412 | AH13: ORTHO!A6 / ORTHO!B6
A14: =IF('ORTHO'!A8="","",'ORTHO'!A8) | B14: =IF('ORTHO'!B8="","",'ORTHO'!B8) | C14: 559605223 | D14: HF549730183 | E14: Optum Care Medical Network of Arizona, Utah, & Washington (LifePrint) | F14: Optum Care Medical Network of Arizona, Utah, & Washington (LifePrint) | G14: No Payer | H14: 46155 | I14: 22853 | J14: ORTHO | K14: =H14+M14 | L14: =K14-TODAY() | M14: 90 | N14: OPTUM | S14: 1 | T14: 1758.12 | U14: 0 | V14: 0 | W14: 1758.12 | X14: 87 | Y14: BURGHER, ABRAM | Z14: ASAP Surgery Centers North Valley LLC | AB14: 46161 | AD14: M50022 | AE14: M50122 | AF14: M5412 | AG14: M5000 | AH14: ORTHO!A8 / ORTHO!B8
A15: =IF('ORTHO'!A8="","",'ORTHO'!A8) | B15: =IF('ORTHO'!B8="","",'ORTHO'!B8) | C15: 559605223 | D15: HF549730183 | E15: Optum Care Medical Network of Arizona, Utah, & Washington (LifePrint) | F15: Optum Care Medical Network of Arizona, Utah, & Washington (LifePrint) | G15: No Payer | H15: 46155 | I15: 22853 | J15: ORTHO | K15: =H15+M15 | L15: =K15-TODAY() | M15: 90 | N15: OPTUM | P15: 59 | S15: 1 | T15: 1758.12 | U15: 0 | V15: 0 | W15: 1758.12 | X15: 87 | Y15: BURGHER, ABRAM | Z15: ASAP Surgery Centers North Valley LLC | AB15: 46161 | AD15: M50023 | AE15: M5412 | AF15: M5000 | AG15: M542 | AH15: ORTHO!A8 / ORTHO!B8
A16: =IF('US'!A10="","",'US'!A10) | B16: =IF('US'!B10="","",'US'!B10) | C16: 560081393 | D16: HF544192008 | E16: United Healthcare | F16: United Healthcare | G16: No Payer | H16: 46155 | I16: 93923 | J16: US | K16: =H16+M16 | L16: =K16-TODAY() | M16: 90 | N16: UHC COMMERCIAL | S16: 1 | T16: 879.06 | U16: 0 | V16: 0 | W16: 879.06 | X16: 87 | Y16: BURGHER, ABRAM | Z16: ASAP - Surprise - Reems | AB16: 46164 | AC16: 46175 | AD16: I739 | AE16: M79604 | AF16: M79605 | AH16: US!A10 / US!B10
A17: =IF('US'!A11="","",'US'!A11) | B17: =IF('US'!B11="","",'US'!B11) | C17: 560081393 | D17: HF544192008 | E17: United Healthcare | F17: United Healthcare | G17: No Payer | H17: 46155 | I17: 93925 | J17: US | K17: =H17+M17 | L17: =K17-TODAY() | M17: 90 | N17: UHC COMMERCIAL | S17: 1 | T17: 1649.2 | U17: 0 | V17: 0 | W17: 1649.2 | X17: 87 | Y17: BURGHER, ABRAM | Z17: ASAP - Surprise - Reems | AB17: 46164 | AC17: 46175 | AD17: I739 | AE17: M79604 | AF17: M79605 | AH17: US!A11 / US!B11
A18: =IF('US'!A12="","",'US'!A12) | B18: =IF('US'!B12="","",'US'!B12) | C18: 560081393 | D18: HF544192008 | E18: United Healthcare | F18: United Healthcare | G18: No Payer | H18: 46155 | I18: 93970 | J18: US | K18: =H18+M18 | L18: =K18-TODAY() | M18: 90 | N18: UHC COMMERCIAL | S18: 1 | T18: 1294.23 | U18: 0 | V18: 0 | W18: 1294.23 | X18: 87 | Y18: BURGHER, ABRAM | Z18: ASAP - Surprise - Reems | AB18: 46164 | AC18: 46175 | AD18: I739 | AE18: M79604 | AF18: M79605 | AH18: US!A12 / US!B12
A19: =IF('BH'!A7="","",'BH'!A7) | B19: =IF('BH'!B7="","",'BH'!B7) | C19: 559331282 | D19: HF479934906 | E19: United Healthcare | F19: United Healthcare | G19: No Payer | H19: 46156 | I19: 99493 | J19: BH | K19: =H19+M19 | L19: =K19-TODAY() | M19: 90 | N19: UHC COMMERCIAL | S19: 1 | T19: 976.64 | U19: 0 | V19: 0 | W19: 976.64 | X19: 86 | Y19: MEARS, CHAD | Z19: ASAP - DEER VALLEY | AB19: 46180 | AD19: F4312 | AH19: BH!A7 / BH!B7
A20: =IF('BH'!A8="","",'BH'!A8) | B20: =IF('BH'!B8="","",'BH'!B8) | C20: 559331282 | D20: HF479934906 | E20: United Healthcare | F20: United Healthcare | G20: No Payer | H20: 46156 | I20: 99494 | J20: BH | K20: =H20+M20 | L20: =K20-TODAY() | M20: 90 | N20: UHC COMMERCIAL | S20: 1 | T20: 396.27 | U20: 0 | V20: 0 | W20: 396.27 | X20: 86 | Y20: MEARS, CHAD | Z20: ASAP - DEER VALLEY | AB20: 46180 | AD20: F4312 | AH20: BH!A8 / BH!B8
A21: =IF('BH'!A9="","",'BH'!A9) | B21: =IF('BH'!B9="","",'BH'!B9) | C21: 559334288 | D21: HF555357253 | E21: United Healthcare | F21: United Healthcare | G21: No Payer | H21: 46156 | I21: 99492 | J21: BH | K21: =H21+M21 | L21: =K21-TODAY() | M21: 90 | N21: UHC COMMERCIAL | S21: 1 | T21: 1029.98 | U21: 0 | V21: 0 | W21: 1029.98 | X21: 86 | Y21: MEARS, CHAD | Z21: ASAP - DEER VALLEY | AB21: 46180 | AD21: F4320 | AH21: BH!A9 / BH!B9
A22: =IF('BH'!A10="","",'BH'!A10) | B22: =IF('BH'!B10="","",'BH'!B10) | C22: 559334288 | D22: HF555357253 | E22: United Healthcare | F22: United Healthcare | G22: No Payer | H22: 46156 | I22: 99494 | J22: BH | K22: =H22+M22 | L22: =K22-TODAY() | M22: 90 | N22: UHC COMMERCIAL | S22: 1 | T22: 396.27 | U22: 0 | V22: 0 | W22: 396.27 | X22: 86 | Y22: MEARS, CHAD | Z22: ASAP - DEER VALLEY | AB22: 46180 | AD22: F4320 | AH22: BH!A10 / BH!B10
A23: =IF('ORTHO'!A9="","",'ORTHO'!A9) | B23: =IF('ORTHO'!B9="","",'ORTHO'!B9) | C23: 559356030 | D23: HF427171307 | E23: HealthSpring Medicare Advantage | F23: HealthSpring Medicare Advantage | G23: No Payer | H23: 46156 | I23: 63047 | J23: ORTHO | K23: =H23+M23 | L23: =K23-TODAY() | M23: 90 | N23: CIGNA / CIGNA MEDICARE | S23: 1 | T23: 7623.07 | U23: 0 | V23: 0 | W23: 7623.07 | X23: 86 | Y23: KRAUSE, JEFFREY | Z23: ASAP Surgery Centers North Valley LLC | AB23: 46160 | AC23: 46170 | AD23: M48062 | AH23: ORTHO!A9 / ORTHO!B9
A24: =IF('US'!A13="","",'US'!A13) | B24: =IF('US'!B13="","",'US'!B13) | C24: 558639899 | D24: HF523293759 | E24: Banner Health & Aetna Health Insurance Company | F24: Banner Health & Aetna Health Insurance Company | G24: No Payer | H24: 46126 | I24: 93923 | J24: US | K24: =H24+M24 | L24: =K24-TODAY() | M24: 120 | N24: BANNER HEALTH & AETNA | S24: 1 | T24: 879.06 | U24: 0 | V24: 0 | W24: 879.06 | X24: 116 | Y24: LEATHEM, JARRETT | Z24: ASAP - Gilbert | AB24: 46141 | AD24: M1712 | AE24: M25562 | AF24: I872 | AH24: US!A13 / US!B13
A25: =IF('DME'!A5="","",'DME'!A5) | B25: =IF('DME'!B5="","",'DME'!B5) | C25: 559604554 | D25: HF549730183 | E25: Optum Care Medical Network of Arizona, Utah, & Washington (LifePrint) | F25: Optum Care Medical Network of Arizona, Utah, & Washington (LifePrint) | G25: LIEN 03 | H25: 46157 | I25: A6023 | J25: DME | K25: =H25+M25 | L25: =K25-TODAY() | M25: 90 | N25: OPTUM | P25: A1 | S25: 20 | T25: 36353.8 | U25: 0 | V25: 0 | W25: 36353.8 | X25: 85 | Y25: MCCUNNIFF, PETER | Z25: ASAP Peoria | AB25: 46217 | AD25: G894 | AE25: M50022 | AF25: M50023 | AG25: M50122 | AH25: DME!A5 / DME!B5
A26: =IF('BH'!A11="","",'BH'!A11) | B26: =IF('BH'!B11="","",'BH'!B11) | C26: 558887755 | D26: HF475049197 | E26: Allwell - All States (Centene) | F26: Allwell - All States (Centene) | G26: Arizona Complete Health (Centene) | H26: 46153 | I26: 99493 | J26: BH | K26: =H26+M26 | L26: =K26-TODAY() | M26: 95 | N26: WELLCARE BY ALLWELL | S26: 1 | T26: 976.64 | U26: 0 | V26: 0 | W26: 976.64 | X26: 89 | Y26: SARKAR, AWNIK | Z26: ASAP Peoria | AB26: 46180 | AD26: F4320 | AH26: BH!A11 / BH!B11
A27: =IF('DME'!A6="","",'DME'!A6) | B27: =IF('DME'!B6="","",'DME'!B6) | C27: 561880042 | D27: HF545888888 | E27: Humana Gold Plus HMO | F27: Humana Gold Plus HMO | G27: No Payer | H27: 46160 | I27: A6023 | J27: DME | K27: =H27+M27 | L27: =K27-TODAY() | M27: 90 | N27: HUMANA MA | O27: ASSUMPTION - shorter of two limits used. 180 days for physicians, 90 for ancillary providers; confirm the provider category. | P27: A2 | S27: 40 | T27: 72707.6 | U27: 0 | V27: 0 | W27: 72707.6 | X27: 82 | Y27: Van Dyke, Sandra | Z27: ASAP - Gilbert | AB27: 46183 | AC27: 46185 | AD27: G894 | AE27: G90523 | AH27: DME!A6 / DME!B6
A28: =IF('DME'!A7="","",'DME'!A7) | B28: =IF('DME'!B7="","",'DME'!B7) | C28: 559742691 | D28: HF543653317 | E28: Optum Care Medical Network of Arizona, Utah, & Washington (LifePrint) | F28: Optum Care Medical Network of Arizona, Utah, & Washington (LifePrint) | G28: No Payer | H28: 46160 | I28: A6010 | J28: DME | K28: =H28+M28 | L28: =K28-TODAY() | M28: 90 | N28: OPTUM | P28: A2 | S28: 20 | T28: 5916.4 | U28: 0 | V28: 0 | W28: 5916.4 | X28: 82 | Y28: TONDINI, JENISE | Z28: ASAP - Goodyear | AB28: 46162 | AC28: 46196 | AD28: G894 | AH28: DME!A7 / DME!B7
A29: =IF('ORTHO'!A10="","",'ORTHO'!A10) | B29: =IF('ORTHO'!B10="","",'ORTHO'!B10) | C29: 565931559 | D29: HF549060053 | E29: Devoted Health Plan | F29: Devoted Health Plan | G29: No Payer | H29: 46190 | I29: 63047 | J29: ORTHO | K29: =H29+M29 | L29: =K29-TODAY() | M29: 60 | N29: DEVOTED | O29: Shortest limit on the reference list. | S29: 1 | T29: 7623.07 | U29: 0 | V29: 0 | W29: 7623.07 | X29: 52 | Y29: MAYURAN, VIKRAM | Z29: ASAP Surgery Centers North Valley LLC | AB29: 46210 | AD29: M48062 | AH29: ORTHO!A10 / ORTHO!B10
A30: =IF('ORTHO'!A11="","",'ORTHO'!A11) | B30: =IF('ORTHO'!B11="","",'ORTHO'!B11) | C30: 565931559 | D30: HF549060053 | E30: Devoted Health Plan | F30: Devoted Health Plan | G30: No Payer | H30: 46190 | I30: 63048 | J30: ORTHO | K30: =H30+M30 | L30: =K30-TODAY() | M30: 60 | N30: DEVOTED | O30: Shortest limit on the reference list. | S30: 1 | T30: 1433.32 | U30: 0 | V30: 0 | W30: 1433.32 | X30: 52 | Y30: MAYURAN, VIKRAM | Z30: ASAP Surgery Centers North Valley LLC | AB30: 46210 | AD30: M48062 | AH30: ORTHO!A11 / ORTHO!B11
A31: =IF('ORTHO'!A12="","",'ORTHO'!A12) | B31: =IF('ORTHO'!B12="","",'ORTHO'!B12) | C31: 561233259 | D31: WC-509516716 | E31: United Healthcare | F31: United Healthcare | G31: No Payer | H31: 46160 | I31: 63047 | J31: ORTHO | K31: =H31+M31 | L31: =K31-TODAY() | M31: 90 | N31: UHC COMMERCIAL | S31: 1 | T31: 7623.07 | U31: 0 | V31: 0 | W31: 7623.07 | X31: 82 | Y31: MAYURAN, VIKRAM | Z31: ASAP Surgery Centers North Valley LLC | AB31: 46177 | AD31: M5416 | AE31: M48061 | AF31: S335XXA | AH31: ORTHO!A12 / ORTHO!B12
A32: =IF('ORTHO'!A13="","",'ORTHO'!A13) | B32: =IF('ORTHO'!B13="","",'ORTHO'!B13) | C32: 561233259 | D32: WC-509516716 | E32: United Healthcare | F32: United Healthcare | G32: No Payer | H32: 46160 | I32: 63048 | J32: ORTHO | K32: =H32+M32 | L32: =K32-TODAY() | M32: 90 | N32: UHC COMMERCIAL | S32: 1 | T32: 1433.32 | U32: 0 | V32: 0 | W32: 1433.32 | X32: 82 | Y32: MAYURAN, VIKRAM | Z32: ASAP Surgery Centers North Valley LLC | AB32: 46177 | AD32: M5416 | AE32: M48061 | AF32: S335XXA | AH32: ORTHO!A13 / ORTHO!B13
A33: =IF('BH'!A13="","",'BH'!A13) | B33: =IF('BH'!B13="","",'BH'!B13) | C33: 559931934 | D33: HF494160468 | E33: UnitedHealthcare Community Plan / Arizona Long Term Care | F33: UnitedHealthcare Community Plan / Arizona Long Term Care | G33: No Payer | H33: 46162 | I33: 99494 | J33: BH | K33: =H33+M33 | L33: =K33-TODAY() | M33: 90 | N33: UHC COMMUNITY | S33: 1 | T33: 396.27 | U33: 0 | V33: 0 | W33: 396.27 | X33: 80 | Y33: O'NEIL, ROY | Z33: ASAP - DEER VALLEY | AB33: 46182 | AC33: 46196 | AD33: F32A | AE33: F411 | AH33: BH!A13 / BH!B13
A34: =IF('BH'!A13="","",'BH'!A13) | B34: =IF('BH'!B13="","",'BH'!B13) | C34: 559931934 | D34: HF494160468 | E34: UnitedHealthcare Community Plan / Arizona Long Term Care | F34: UnitedHealthcare Community Plan / Arizona Long Term Care | G34: No Payer | H34: 46162 | I34: 99494 | J34: BH | K34: =H34+M34 | L34: =K34-TODAY() | M34: 90 | N34: UHC COMMUNITY | S34: 1 | T34: 396.27 | U34: 0 | V34: 0 | W34: 396.27 | X34: 80 | Y34: O'NEIL, ROY | Z34: ASAP - DEER VALLEY | AB34: 46182 | AC34: 46196 | AD34: F32A | AE34: F411 | AH34: BH!A13 / BH!B13
A35: =IF('BH'!A14="","",'BH'!A14) | B35: =IF('BH'!B14="","",'BH'!B14) | C35: 560175340 | D35: HF485806241 | E35: UnitedHealthcare Community Plan / Arizona Long Term Care | F35: UnitedHealthcare Community Plan / Arizona Long Term Care | G35: UnitedHealthcare Community Plan / Arizona Long Term Care | H35: 46162 | I35: 99494 | J35: BH | K35: =H35+M35 | L35: =K35-TODAY() | M35: 90 | N35: UHC COMMUNITY | S35: 1 | T35: 396.27 | U35: 0 | V35: 0 | W35: 396.27 | X35: 80 | Y35: TURLEY, TODD | Z35: ASAP - DEER VALLEY | AB35: 46182 | AC35: 46195 | AD35: F1190 | AE35: F32A | AH35: BH!A14 / BH!B14
A36: =IF('ORTHO'!A14="","",'ORTHO'!A14) | B36: =IF('ORTHO'!B14="","",'ORTHO'!B14) | C36: 559340087 | D36: HF522538764 | E36: Allwell - All States (Centene) | F36: Allwell - All States (Centene) | G36: No Payer | H36: 46157 | I36: 63685 | J36: ORTHO | K36: =H36+M36 | L36: =K36-TODAY() | M36: 95 | N36: WELLCARE BY ALLWELL | S36: 1 | T36: 2493.33 | U36: 0 | V36: 0 | W36: 2493.33 | X36: 85 | Y36: O'NEIL, ROY | Z36: ASAP Surgery Centers North Valley LLC | AB36: 46160 | AC36: 46170 | AD36: M961 | AE36: M5416 | AF36: G894 | AH36: ORTHO!A14 / ORTHO!B14
A37: =IF('DME'!A8="","",'DME'!A8) | B37: =IF('DME'!B8="","",'DME'!B8) | C37: 561237046 | D37: HF533960930 | E37: UnitedHealthcare Community Plan / Arizona Long Term Care | F37: UnitedHealthcare Community Plan / Arizona Long Term Care | G37: Molina Complete Care of Arizona (Magellan Complete Care AZ) | H37: 46163 | I37: A6010 | J37: DME | K37: =H37+M37 | L37: =K37-TODAY() | M37: 90 | N37: UHC COMMUNITY | P37: A1 | S37: 10 | T37: 2958.2 | U37: 0 | V37: 0 | W37: 2958.2 | X37: 79 | Y37: LUKE, TIMOTHY | Z37: ASAP - DEER VALLEY | AB37: 46177 | AC37: 46183 | AD37: M5030 | AE37: M5412 | AH37: DME!A8 / DME!B8
A38: =IF('ORTHO'!A15="","",'ORTHO'!A15) | B38: =IF('ORTHO'!B15="","",'ORTHO'!B15) | C38: 561246589 | D38: HF554018380 | E38: UnitedHealthcare Community Plan / Arizona Long Term Care | F38: UnitedHealthcare Community Plan / Arizona Long Term Care | G38: No Payer | H38: 46163 | I38: 63030 | J38: ORTHO | K38: =H38+M38 | L38: =K38-TODAY() | M38: 90 | N38: UHC COMMUNITY | P38: RT | S38: 1 | T38: 6297.27 | U38: 0 | V38: 0 | W38: 6297.27 | X38: 79 | Y38: LUKE, TIMOTHY | Z38: ASAP Surgery Centers North Valley LLC | AB38: 46177 | AC38: 46183 | AD38: M4807 | AE38: M5417 | AF38: M5127 | AH38: ORTHO!A15 / ORTHO!B15
A39: =IF('US'!A14="","",'US'!A14) | B39: =IF('US'!B14="","",'US'!B14) | C39: 560709048 | D39: HF330335441 | E39: HealthSpring Medicare Advantage | F39: HealthSpring Medicare Advantage | G39: No Payer | H39: 46163 | I39: 93923 | J39: US | K39: =H39+M39 | L39: =K39-TODAY() | M39: 90 | N39: CIGNA / CIGNA MEDICARE | S39: 1 | T39: 879.06 | U39: 0 | V39: 0 | W39: 879.06 | X39: 79 | Y39: TURLEY, TODD | Z39: ASAP - DEER VALLEY 240 | AB39: 46171 | AC39: 46182 | AD39: R2243 | AH39: US!A14 / US!B14
A40: =IF('US'!A15="","",'US'!A15) | B40: =IF('US'!B15="","",'US'!B15) | C40: 560709048 | D40: HF330335441 | E40: HealthSpring Medicare Advantage | F40: HealthSpring Medicare Advantage | G40: No Payer | H40: 46163 | I40: 93925 | J40: US | K40: =H40+M40 | L40: =K40-TODAY() | M40: 90 | N40: CIGNA / CIGNA MEDICARE | S40: 1 | T40: 1649.2 | U40: 0 | V40: 0 | W40: 1649.2 | X40: 79 | Y40: TURLEY, TODD | Z40: ASAP - DEER VALLEY 240 | AB40: 46171 | AC40: 46182 | AD40: R2243 | AH40: US!A15 / US!B15
A41: =IF('US'!A16="","",'US'!A16) | B41: =IF('US'!B16="","",'US'!B16) | C41: 560710074 | D41: HF556870121 | E41: United Healthcare | F41: United Healthcare | G41: No Payer | H41: 46163 | I41: 93923 | J41: US | K41: =H41+M41 | L41: =K41-TODAY() | M41: 90 | N41: UHC COMMERCIAL | S41: 1 | T41: 879.06 | U41: 0 | V41: 0 | W41: 879.06 | X41: 79 | Y41: TURLEY, TODD | Z41: ASAP - DEER VALLEY 240 | AB41: 46171 | AD41: R2242 | AH41: US!A16 / US!B16
...
